{"level":"ERROR","location":"[exception:108] fyers_logger","message":"HTTPSConnectionPool(host='api-t1.fyers.in', port=443): Max retries exceeded with url: /data/symbol-token (Caused by NewConnectionError('<urllib3.connection.HTTPSConnection object at 0x000001D155D29E80>: Failed to establish a new connection: [Errno 11001] getaddrinfo failed'))","timestamp":"2025-06-25 15:28:17,670+0530","service":"FyersDataSocket","exception":"Traceback (most recent call last):\n  File \"C:\\Users\\Siddhi Waghmare\\AppData\\Roaming\\Python\\Python39\\site-packages\\websocket\\_app.py\", line 428, in setSock\n    dispatcher.read(self.sock.sock, read, check)\n  File \"C:\\Users\\Siddhi Waghmare\\AppData\\Roaming\\Python\\Python39\\site-packages\\websocket\\_app.py\", line 99, in read\n    if not read_callback():\n  File \"C:\\Users\\Siddhi Waghmare\\AppData\\Roaming\\Python\\Python39\\site-packages\\websocket\\_app.py\", line 437, in read\n    op_code, frame = self.sock.recv_data_frame(True)\n  File \"C:\\Users\\Siddhi Waghmare\\AppData\\Roaming\\Python\\Python39\\site-packages\\websocket\\_core.py\", line 406, in recv_data_frame\n    frame = self.recv_frame()\n  File \"C:\\Users\\Siddhi Waghmare\\AppData\\Roaming\\Python\\Python39\\site-packages\\websocket\\_core.py\", line 445, in recv_frame\n    return self.frame_buffer.recv_frame()\n  File \"C:\\Users\\Siddhi Waghmare\\AppData\\Roaming\\Python\\Python39\\site-packages\\websocket\\_abnf.py\", line 338, in recv_frame\n    self.recv_header()\n  File \"C:\\Users\\Siddhi Waghmare\\AppData\\Roaming\\Python\\Python39\\site-packages\\websocket\\_abnf.py\", line 294, in recv_header\n    header = self.recv_strict(2)\n  File \"C:\\Users\\Siddhi Waghmare\\AppData\\Roaming\\Python\\Python39\\site-packages\\websocket\\_abnf.py\", line 373, in recv_strict\n    bytes_ = self.recv(min(16384, shortage))\n  File \"C:\\Users\\Siddhi Waghmare\\AppData\\Roaming\\Python\\Python39\\site-packages\\websocket\\_core.py\", line 529, in _recv\n    return recv(self.sock, bufsize)\n  File \"C:\\Users\\Siddhi Waghmare\\AppData\\Roaming\\Python\\Python39\\site-packages\\websocket\\_socket.py\", line 108, in recv\n    bytes_ = _recv()\n  File \"C:\\Users\\Siddhi Waghmare\\AppData\\Roaming\\Python\\Python39\\site-packages\\websocket\\_socket.py\", line 87, in _recv\n    return sock.recv(bufsize)\n  File \"C:\\Program Files\\Python39\\lib\\ssl.py\", line 1226, in recv\n    return self.read(buflen)\n  File \"C:\\Program Files\\Python39\\lib\\ssl.py\", line 1101, in read\n    return self._sslobj.read(len)\nConnectionResetError: [WinError 10054] An existing connection was forcibly closed by the remote host\n\nDuring handling of the above exception, another exception occurred:\n\nTraceback (most recent call last):\n  File \"C:\\Users\\Siddhi Waghmare\\AppData\\Roaming\\Python\\Python39\\site-packages\\websocket\\_app.py\", line 547, in _callback\n    callback(self, *args)\n  File \"C:\\Users\\Siddhi Waghmare\\AppData\\Roaming\\Python\\Python39\\site-packages\\fyers_apiv3\\FyersWebsocket\\data_ws.py\", line 1663, in <lambda>\n    on_error=lambda ws, msg: self.On_error(msg),\n  File \"C:\\Users\\Siddhi Waghmare\\AppData\\Roaming\\Python\\Python39\\site-packages\\fyers_apiv3\\FyersWebsocket\\data_ws.py\", line 1500, in On_error\n    self.OnError(message)\n  File \"c:\\Users\\Siddhi Waghmare\\Desktop\\Projects\\Trade_Executor\\backend\\webscoket_test.py\", line 21, in onerror\n    def onclose(message):\n  File \"C:\\Program Files\\Python39\\lib\\encodings\\cp1252.py\", line 19, in encode\n    return codecs.charmap_encode(input,self.errors,encoding_table)[0]\nUnicodeEncodeError: 'charmap' codec can't encode character '\\u274c' in position 0: character maps to <undefined>\n\nDuring handling of the above exception, another exception occurred:\n\nTraceback (most recent call last):\n  File \"C:\\Users\\Siddhi Waghmare\\AppData\\Roaming\\Python\\Python39\\site-packages\\websocket\\_app.py\", line 501, in run_forever\n    setSock()\n  File \"C:\\Users\\Siddhi Waghmare\\AppData\\Roaming\\Python\\Python39\\site-packages\\websocket\\_app.py\", line 430, in setSock\n    handleDisconnect(e, reconnecting)\n  File \"C:\\Users\\Siddhi Waghmare\\AppData\\Roaming\\Python\\Python39\\site-packages\\websocket\\_app.py\", line 481, in handleDisconnect\n    self._callback(self.on_error, e)\n  File \"C:\\Users\\Siddhi Waghmare\\AppData\\Roaming\\Python\\Python39\\site-packages\\websocket\\_app.py\", line 552, in _callback\n    self.on_error(self, e)\n  File \"C:\\Users\\Siddhi Waghmare\\AppData\\Roaming\\Python\\Python39\\site-packages\\fyers_apiv3\\FyersWebsocket\\data_ws.py\", line 1663, in <lambda>\n    on_error=lambda ws, msg: self.On_error(msg),\n  File \"C:\\Users\\Siddhi Waghmare\\AppData\\Roaming\\Python\\Python39\\site-packages\\fyers_apiv3\\FyersWebsocket\\data_ws.py\", line 1500, in On_error\n    self.OnError(message)\n  File \"c:\\Users\\Siddhi Waghmare\\Desktop\\Projects\\Trade_Executor\\backend\\webscoket_test.py\", line 21, in onerror\n    def onclose(message):\n  File \"C:\\Program Files\\Python39\\lib\\encodings\\cp1252.py\", line 19, in encode\n    return codecs.charmap_encode(input,self.errors,encoding_table)[0]\nUnicodeEncodeError: 'charmap' codec can't encode character '\\u274c' in position 0: character maps to <undefined>\n\nDuring handling of the above exception, another exception occurred:\n\nTraceback (most recent call last):\n  File \"C:\\Users\\Siddhi Waghmare\\AppData\\Roaming\\Python\\Python39\\site-packages\\urllib3\\connection.py\", line 174, in _new_conn\n    conn = connection.create_connection(\n  File \"C:\\Users\\Siddhi Waghmare\\AppData\\Roaming\\Python\\Python39\\site-packages\\urllib3\\util\\connection.py\", line 72, in create_connection\n    for res in socket.getaddrinfo(host, port, family, socket.SOCK_STREAM):\n  File \"C:\\Program Files\\Python39\\lib\\socket.py\", line 953, in getaddrinfo\n    for res in _socket.getaddrinfo(host, port, family, type, proto, flags):\nsocket.gaierror: [Errno 11001] getaddrinfo failed\n\nDuring handling of the above exception, another exception occurred:\n\nTraceback (most recent call last):\n  File \"C:\\Users\\Siddhi Waghmare\\AppData\\Roaming\\Python\\Python39\\site-packages\\urllib3\\connectionpool.py\", line 716, in urlopen\n    httplib_response = self._make_request(\n  File \"C:\\Users\\Siddhi Waghmare\\AppData\\Roaming\\Python\\Python39\\site-packages\\urllib3\\connectionpool.py\", line 404, in _make_request\n    self._validate_conn(conn)\n  File \"C:\\Users\\Siddhi Waghmare\\AppData\\Roaming\\Python\\Python39\\site-packages\\urllib3\\connectionpool.py\", line 1061, in _validate_conn\n    conn.connect()\n  File \"C:\\Users\\Siddhi Waghmare\\AppData\\Roaming\\Python\\Python39\\site-packages\\urllib3\\connection.py\", line 363, in connect\n    self.sock = conn = self._new_conn()\n  File \"C:\\Users\\Siddhi Waghmare\\AppData\\Roaming\\Python\\Python39\\site-packages\\urllib3\\connection.py\", line 186, in _new_conn\n    raise NewConnectionError(\nurllib3.exceptions.NewConnectionError: <urllib3.connection.HTTPSConnection object at 0x000001D155D29E80>: Failed to establish a new connection: [Errno 11001] getaddrinfo failed\n\nDuring handling of the above exception, another exception occurred:\n\nTraceback (most recent call last):\n  File \"C:\\Users\\Siddhi Waghmare\\AppData\\Roaming\\Python\\Python39\\site-packages\\requests\\adapters.py\", line 486, in send\n    resp = conn.urlopen(\n  File \"C:\\Users\\Siddhi Waghmare\\AppData\\Roaming\\Python\\Python39\\site-packages\\urllib3\\connectionpool.py\", line 802, in urlopen\n    retries = retries.increment(\n  File \"C:\\Users\\Siddhi Waghmare\\AppData\\Roaming\\Python\\Python39\\site-packages\\urllib3\\util\\retry.py\", line 594, in increment\n    raise MaxRetryError(_pool, url, error or ResponseError(cause))\nurllib3.exceptions.MaxRetryError: HTTPSConnectionPool(host='api-t1.fyers.in', port=443): Max retries exceeded with url: /data/symbol-token (Caused by NewConnectionError('<urllib3.connection.HTTPSConnection object at 0x000001D155D29E80>: Failed to establish a new connection: [Errno 11001] getaddrinfo failed'))\n\nDuring handling of the above exception, another exception occurred:\n\nTraceback (most recent call last):\n  File \"C:\\Users\\Siddhi Waghmare\\AppData\\Roaming\\Python\\Python39\\site-packages\\fyers_apiv3\\FyersWebsocket\\data_ws.py\", line 63, in symbol_to_hsmtoken\n    response = requests.post(\n  File \"C:\\Users\\Siddhi Waghmare\\AppData\\Roaming\\Python\\Python39\\site-packages\\requests\\api.py\", line 115, in post\n    return request(\"post\", url, data=data, json=json, **kwargs)\n  File \"C:\\Users\\Siddhi Waghmare\\AppData\\Roaming\\Python\\Python39\\site-packages\\requests\\api.py\", line 59, in request\n    return session.request(method=method, url=url, **kwargs)\n  File \"C:\\Users\\Siddhi Waghmare\\AppData\\Roaming\\Python\\Python39\\site-packages\\requests\\sessions.py\", line 589, in request\n    resp = self.send(prep, **send_kwargs)\n  File \"C:\\Users\\Siddhi Waghmare\\AppData\\Roaming\\Python\\Python39\\site-packages\\requests\\sessions.py\", line 703, in send\n    r = adapter.send(request, **kwargs)\n  File \"C:\\Users\\Siddhi Waghmare\\AppData\\Roaming\\Python\\Python39\\site-packages\\requests\\adapters.py\", line 519, in send\n    raise ConnectionError(e, request=request)\nrequests.exceptions.ConnectionError: HTTPSConnectionPool(host='api-t1.fyers.in', port=443): Max retries exceeded with url: /data/symbol-token (Caused by NewConnectionError('<urllib3.connection.HTTPSConnection object at 0x000001D155D29E80>: Failed to establish a new connection: [Errno 11001] getaddrinfo failed'))","exception_name":"ConnectionError"}
{"level":"ERROR","location":"[exception:108] fyers_logger","message":"'NoneType' object is not subscriptable","timestamp":"2025-06-25 15:28:17,940+0530","service":"FyersDataSocket","exception":"Traceback (most recent call last):\n  File \"C:\\Users\\Siddhi Waghmare\\AppData\\Roaming\\Python\\Python39\\site-packages\\websocket\\_app.py\", line 428, in setSock\n    dispatcher.read(self.sock.sock, read, check)\n  File \"C:\\Users\\Siddhi Waghmare\\AppData\\Roaming\\Python\\Python39\\site-packages\\websocket\\_app.py\", line 99, in read\n    if not read_callback():\n  File \"C:\\Users\\Siddhi Waghmare\\AppData\\Roaming\\Python\\Python39\\site-packages\\websocket\\_app.py\", line 437, in read\n    op_code, frame = self.sock.recv_data_frame(True)\n  File \"C:\\Users\\Siddhi Waghmare\\AppData\\Roaming\\Python\\Python39\\site-packages\\websocket\\_core.py\", line 406, in recv_data_frame\n    frame = self.recv_frame()\n  File \"C:\\Users\\Siddhi Waghmare\\AppData\\Roaming\\Python\\Python39\\site-packages\\websocket\\_core.py\", line 445, in recv_frame\n    return self.frame_buffer.recv_frame()\n  File \"C:\\Users\\Siddhi Waghmare\\AppData\\Roaming\\Python\\Python39\\site-packages\\websocket\\_abnf.py\", line 338, in recv_frame\n    self.recv_header()\n  File \"C:\\Users\\Siddhi Waghmare\\AppData\\Roaming\\Python\\Python39\\site-packages\\websocket\\_abnf.py\", line 294, in recv_header\n    header = self.recv_strict(2)\n  File \"C:\\Users\\Siddhi Waghmare\\AppData\\Roaming\\Python\\Python39\\site-packages\\websocket\\_abnf.py\", line 373, in recv_strict\n    bytes_ = self.recv(min(16384, shortage))\n  File \"C:\\Users\\Siddhi Waghmare\\AppData\\Roaming\\Python\\Python39\\site-packages\\websocket\\_core.py\", line 529, in _recv\n    return recv(self.sock, bufsize)\n  File \"C:\\Users\\Siddhi Waghmare\\AppData\\Roaming\\Python\\Python39\\site-packages\\websocket\\_socket.py\", line 108, in recv\n    bytes_ = _recv()\n  File \"C:\\Users\\Siddhi Waghmare\\AppData\\Roaming\\Python\\Python39\\site-packages\\websocket\\_socket.py\", line 87, in _recv\n    return sock.recv(bufsize)\n  File \"C:\\Program Files\\Python39\\lib\\ssl.py\", line 1226, in recv\n    return self.read(buflen)\n  File \"C:\\Program Files\\Python39\\lib\\ssl.py\", line 1101, in read\n    return self._sslobj.read(len)\nConnectionResetError: [WinError 10054] An existing connection was forcibly closed by the remote host\n\nDuring handling of the above exception, another exception occurred:\n\nTraceback (most recent call last):\n  File \"C:\\Users\\Siddhi Waghmare\\AppData\\Roaming\\Python\\Python39\\site-packages\\websocket\\_app.py\", line 547, in _callback\n    callback(self, *args)\n  File \"C:\\Users\\Siddhi Waghmare\\AppData\\Roaming\\Python\\Python39\\site-packages\\fyers_apiv3\\FyersWebsocket\\data_ws.py\", line 1663, in <lambda>\n    on_error=lambda ws, msg: self.On_error(msg),\n  File \"C:\\Users\\Siddhi Waghmare\\AppData\\Roaming\\Python\\Python39\\site-packages\\fyers_apiv3\\FyersWebsocket\\data_ws.py\", line 1500, in On_error\n    self.OnError(message)\n  File \"c:\\Users\\Siddhi Waghmare\\Desktop\\Projects\\Trade_Executor\\backend\\webscoket_test.py\", line 21, in onerror\n    def onclose(message):\n  File \"C:\\Program Files\\Python39\\lib\\encodings\\cp1252.py\", line 19, in encode\n    return codecs.charmap_encode(input,self.errors,encoding_table)[0]\nUnicodeEncodeError: 'charmap' codec can't encode character '\\u274c' in position 0: character maps to <undefined>\n\nDuring handling of the above exception, another exception occurred:\n\nTraceback (most recent call last):\n  File \"C:\\Users\\Siddhi Waghmare\\AppData\\Roaming\\Python\\Python39\\site-packages\\websocket\\_app.py\", line 501, in run_forever\n    setSock()\n  File \"C:\\Users\\Siddhi Waghmare\\AppData\\Roaming\\Python\\Python39\\site-packages\\websocket\\_app.py\", line 430, in setSock\n    handleDisconnect(e, reconnecting)\n  File \"C:\\Users\\Siddhi Waghmare\\AppData\\Roaming\\Python\\Python39\\site-packages\\websocket\\_app.py\", line 481, in handleDisconnect\n    self._callback(self.on_error, e)\n  File \"C:\\Users\\Siddhi Waghmare\\AppData\\Roaming\\Python\\Python39\\site-packages\\websocket\\_app.py\", line 552, in _callback\n    self.on_error(self, e)\n  File \"C:\\Users\\Siddhi Waghmare\\AppData\\Roaming\\Python\\Python39\\site-packages\\fyers_apiv3\\FyersWebsocket\\data_ws.py\", line 1663, in <lambda>\n    on_error=lambda ws, msg: self.On_error(msg),\n  File \"C:\\Users\\Siddhi Waghmare\\AppData\\Roaming\\Python\\Python39\\site-packages\\fyers_apiv3\\FyersWebsocket\\data_ws.py\", line 1500, in On_error\n    self.OnError(message)\n  File \"c:\\Users\\Siddhi Waghmare\\Desktop\\Projects\\Trade_Executor\\backend\\webscoket_test.py\", line 21, in onerror\n    def onclose(message):\n  File \"C:\\Program Files\\Python39\\lib\\encodings\\cp1252.py\", line 19, in encode\n    return codecs.charmap_encode(input,self.errors,encoding_table)[0]\nUnicodeEncodeError: 'charmap' codec can't encode character '\\u274c' in position 0: character maps to <undefined>\n\nDuring handling of the above exception, another exception occurred:\n\nTraceback (most recent call last):\n  File \"C:\\Users\\Siddhi Waghmare\\AppData\\Roaming\\Python\\Python39\\site-packages\\fyers_apiv3\\FyersWebsocket\\data_ws.py\", line 1333, in __symbol_conversion\n    if symbol_value[3] != \"\":\nTypeError: 'NoneType' object is not subscriptable","exception_name":"TypeError"}
{"level":"ERROR","location":"[exception:108] fyers_logger","message":"HTTPSConnectionPool(host='api-t1.fyers.in', port=443): Max retries exceeded with url: /data/symbol-token (Caused by NewConnectionError('<urllib3.connection.HTTPSConnection object at 0x000001D155D22E80>: Failed to establish a new connection: [Errno 11001] getaddrinfo failed'))","timestamp":"2025-06-25 15:28:22,682+0530","service":"FyersDataSocket","exception":"Traceback (most recent call last):\n  File \"C:\\Users\\Siddhi Waghmare\\AppData\\Roaming\\Python\\Python39\\site-packages\\websocket\\_http.py\", line 155, in _get_addrinfo_list\n    addrinfo_list = socket.getaddrinfo(\n  File \"C:\\Program Files\\Python39\\lib\\socket.py\", line 953, in getaddrinfo\n    for res in _socket.getaddrinfo(host, port, family, type, proto, flags):\nsocket.gaierror: [Errno 11001] getaddrinfo failed\n\nDuring handling of the above exception, another exception occurred:\n\nTraceback (most recent call last):\n  File \"C:\\Users\\Siddhi Waghmare\\AppData\\Roaming\\Python\\Python39\\site-packages\\websocket\\_app.py\", line 412, in setSock\n    self.sock.connect(\n  File \"C:\\Users\\Siddhi Waghmare\\AppData\\Roaming\\Python\\Python39\\site-packages\\websocket\\_core.py\", line 249, in connect\n    self.sock, addrs = connect(url, self.sock_opt, proxy_info(**options),\n  File \"C:\\Users\\Siddhi Waghmare\\AppData\\Roaming\\Python\\Python39\\site-packages\\websocket\\_http.py\", line 122, in connect\n    addrinfo_list, need_tunnel, auth = _get_addrinfo_list(\n  File \"C:\\Users\\Siddhi Waghmare\\AppData\\Roaming\\Python\\Python39\\site-packages\\websocket\\_http.py\", line 167, in _get_addrinfo_list\n    raise WebSocketAddressException(e)\nwebsocket._exceptions.WebSocketAddressException: [Errno 11001] getaddrinfo failed\n\nDuring handling of the above exception, another exception occurred:\n\nTraceback (most recent call last):\n  File \"C:\\Users\\Siddhi Waghmare\\AppData\\Roaming\\Python\\Python39\\site-packages\\websocket\\_app.py\", line 547, in _callback\n    callback(self, *args)\n  File \"C:\\Users\\Siddhi Waghmare\\AppData\\Roaming\\Python\\Python39\\site-packages\\fyers_apiv3\\FyersWebsocket\\data_ws.py\", line 1663, in <lambda>\n    on_error=lambda ws, msg: self.On_error(msg),\n  File \"C:\\Users\\Siddhi Waghmare\\AppData\\Roaming\\Python\\Python39\\site-packages\\fyers_apiv3\\FyersWebsocket\\data_ws.py\", line 1500, in On_error\n    self.OnError(message)\n  File \"c:\\Users\\Siddhi Waghmare\\Desktop\\Projects\\Trade_Executor\\backend\\webscoket_test.py\", line 21, in onerror\n    def onclose(message):\n  File \"C:\\Program Files\\Python39\\lib\\encodings\\cp1252.py\", line 19, in encode\n    return codecs.charmap_encode(input,self.errors,encoding_table)[0]\nUnicodeEncodeError: 'charmap' codec can't encode character '\\u274c' in position 0: character maps to <undefined>\n\nDuring handling of the above exception, another exception occurred:\n\nTraceback (most recent call last):\n  File \"C:\\Users\\Siddhi Waghmare\\AppData\\Roaming\\Python\\Python39\\site-packages\\websocket\\_app.py\", line 501, in run_forever\n    setSock()\n  File \"C:\\Users\\Siddhi Waghmare\\AppData\\Roaming\\Python\\Python39\\site-packages\\websocket\\_app.py\", line 430, in setSock\n    handleDisconnect(e, reconnecting)\n  File \"C:\\Users\\Siddhi Waghmare\\AppData\\Roaming\\Python\\Python39\\site-packages\\websocket\\_app.py\", line 481, in handleDisconnect\n    self._callback(self.on_error, e)\n  File \"C:\\Users\\Siddhi Waghmare\\AppData\\Roaming\\Python\\Python39\\site-packages\\websocket\\_app.py\", line 552, in _callback\n    self.on_error(self, e)\n  File \"C:\\Users\\Siddhi Waghmare\\AppData\\Roaming\\Python\\Python39\\site-packages\\fyers_apiv3\\FyersWebsocket\\data_ws.py\", line 1663, in <lambda>\n    on_error=lambda ws, msg: self.On_error(msg),\n  File \"C:\\Users\\Siddhi Waghmare\\AppData\\Roaming\\Python\\Python39\\site-packages\\fyers_apiv3\\FyersWebsocket\\data_ws.py\", line 1500, in On_error\n    self.OnError(message)\n  File \"c:\\Users\\Siddhi Waghmare\\Desktop\\Projects\\Trade_Executor\\backend\\webscoket_test.py\", line 21, in onerror\n    def onclose(message):\n  File \"C:\\Program Files\\Python39\\lib\\encodings\\cp1252.py\", line 19, in encode\n    return codecs.charmap_encode(input,self.errors,encoding_table)[0]\nUnicodeEncodeError: 'charmap' codec can't encode character '\\u274c' in position 0: character maps to <undefined>\n\nDuring handling of the above exception, another exception occurred:\n\nTraceback (most recent call last):\n  File \"C:\\Users\\Siddhi Waghmare\\AppData\\Roaming\\Python\\Python39\\site-packages\\urllib3\\connection.py\", line 174, in _new_conn\n    conn = connection.create_connection(\n  File \"C:\\Users\\Siddhi Waghmare\\AppData\\Roaming\\Python\\Python39\\site-packages\\urllib3\\util\\connection.py\", line 72, in create_connection\n    for res in socket.getaddrinfo(host, port, family, socket.SOCK_STREAM):\n  File \"C:\\Program Files\\Python39\\lib\\socket.py\", line 953, in getaddrinfo\n    for res in _socket.getaddrinfo(host, port, family, type, proto, flags):\nsocket.gaierror: [Errno 11001] getaddrinfo failed\n\nDuring handling of the above exception, another exception occurred:\n\nTraceback (most recent call last):\n  File \"C:\\Users\\Siddhi Waghmare\\AppData\\Roaming\\Python\\Python39\\site-packages\\urllib3\\connectionpool.py\", line 716, in urlopen\n    httplib_response = self._make_request(\n  File \"C:\\Users\\Siddhi Waghmare\\AppData\\Roaming\\Python\\Python39\\site-packages\\urllib3\\connectionpool.py\", line 404, in _make_request\n    self._validate_conn(conn)\n  File \"C:\\Users\\Siddhi Waghmare\\AppData\\Roaming\\Python\\Python39\\site-packages\\urllib3\\connectionpool.py\", line 1061, in _validate_conn\n    conn.connect()\n  File \"C:\\Users\\Siddhi Waghmare\\AppData\\Roaming\\Python\\Python39\\site-packages\\urllib3\\connection.py\", line 363, in connect\n    self.sock = conn = self._new_conn()\n  File \"C:\\Users\\Siddhi Waghmare\\AppData\\Roaming\\Python\\Python39\\site-packages\\urllib3\\connection.py\", line 186, in _new_conn\n    raise NewConnectionError(\nurllib3.exceptions.NewConnectionError: <urllib3.connection.HTTPSConnection object at 0x000001D155D22E80>: Failed to establish a new connection: [Errno 11001] getaddrinfo failed\n\nDuring handling of the above exception, another exception occurred:\n\nTraceback (most recent call last):\n  File \"C:\\Users\\Siddhi Waghmare\\AppData\\Roaming\\Python\\Python39\\site-packages\\requests\\adapters.py\", line 486, in send\n    resp = conn.urlopen(\n  File \"C:\\Users\\Siddhi Waghmare\\AppData\\Roaming\\Python\\Python39\\site-packages\\urllib3\\connectionpool.py\", line 802, in urlopen\n    retries = retries.increment(\n  File \"C:\\Users\\Siddhi Waghmare\\AppData\\Roaming\\Python\\Python39\\site-packages\\urllib3\\util\\retry.py\", line 594, in increment\n    raise MaxRetryError(_pool, url, error or ResponseError(cause))\nurllib3.exceptions.MaxRetryError: HTTPSConnectionPool(host='api-t1.fyers.in', port=443): Max retries exceeded with url: /data/symbol-token (Caused by NewConnectionError('<urllib3.connection.HTTPSConnection object at 0x000001D155D22E80>: Failed to establish a new connection: [Errno 11001] getaddrinfo failed'))\n\nDuring handling of the above exception, another exception occurred:\n\nTraceback (most recent call last):\n  File \"C:\\Users\\Siddhi Waghmare\\AppData\\Roaming\\Python\\Python39\\site-packages\\fyers_apiv3\\FyersWebsocket\\data_ws.py\", line 63, in symbol_to_hsmtoken\n    response = requests.post(\n  File \"C:\\Users\\Siddhi Waghmare\\AppData\\Roaming\\Python\\Python39\\site-packages\\requests\\api.py\", line 115, in post\n    return request(\"post\", url, data=data, json=json, **kwargs)\n  File \"C:\\Users\\Siddhi Waghmare\\AppData\\Roaming\\Python\\Python39\\site-packages\\requests\\api.py\", line 59, in request\n    return session.request(method=method, url=url, **kwargs)\n  File \"C:\\Users\\Siddhi Waghmare\\AppData\\Roaming\\Python\\Python39\\site-packages\\requests\\sessions.py\", line 589, in request\n    resp = self.send(prep, **send_kwargs)\n  File \"C:\\Users\\Siddhi Waghmare\\AppData\\Roaming\\Python\\Python39\\site-packages\\requests\\sessions.py\", line 703, in send\n    r = adapter.send(request, **kwargs)\n  File \"C:\\Users\\Siddhi Waghmare\\AppData\\Roaming\\Python\\Python39\\site-packages\\requests\\adapters.py\", line 519, in send\n    raise ConnectionError(e, request=request)\nrequests.exceptions.ConnectionError: HTTPSConnectionPool(host='api-t1.fyers.in', port=443): Max retries exceeded with url: /data/symbol-token (Caused by NewConnectionError('<urllib3.connection.HTTPSConnection object at 0x000001D155D22E80>: Failed to establish a new connection: [Errno 11001] getaddrinfo failed'))","exception_name":"ConnectionError"}
{"level":"ERROR","location":"[exception:108] fyers_logger","message":"'NoneType' object is not subscriptable","timestamp":"2025-06-25 15:28:22,723+0530","service":"FyersDataSocket","exception":"Traceback (most recent call last):\n  File \"C:\\Users\\Siddhi Waghmare\\AppData\\Roaming\\Python\\Python39\\site-packages\\websocket\\_http.py\", line 155, in _get_addrinfo_list\n    addrinfo_list = socket.getaddrinfo(\n  File \"C:\\Program Files\\Python39\\lib\\socket.py\", line 953, in getaddrinfo\n    for res in _socket.getaddrinfo(host, port, family, type, proto, flags):\nsocket.gaierror: [Errno 11001] getaddrinfo failed\n\nDuring handling of the above exception, another exception occurred:\n\nTraceback (most recent call last):\n  File \"C:\\Users\\Siddhi Waghmare\\AppData\\Roaming\\Python\\Python39\\site-packages\\websocket\\_app.py\", line 412, in setSock\n    self.sock.connect(\n  File \"C:\\Users\\Siddhi Waghmare\\AppData\\Roaming\\Python\\Python39\\site-packages\\websocket\\_core.py\", line 249, in connect\n    self.sock, addrs = connect(url, self.sock_opt, proxy_info(**options),\n  File \"C:\\Users\\Siddhi Waghmare\\AppData\\Roaming\\Python\\Python39\\site-packages\\websocket\\_http.py\", line 122, in connect\n    addrinfo_list, need_tunnel, auth = _get_addrinfo_list(\n  File \"C:\\Users\\Siddhi Waghmare\\AppData\\Roaming\\Python\\Python39\\site-packages\\websocket\\_http.py\", line 167, in _get_addrinfo_list\n    raise WebSocketAddressException(e)\nwebsocket._exceptions.WebSocketAddressException: [Errno 11001] getaddrinfo failed\n\nDuring handling of the above exception, another exception occurred:\n\nTraceback (most recent call last):\n  File \"C:\\Users\\Siddhi Waghmare\\AppData\\Roaming\\Python\\Python39\\site-packages\\websocket\\_app.py\", line 547, in _callback\n    callback(self, *args)\n  File \"C:\\Users\\Siddhi Waghmare\\AppData\\Roaming\\Python\\Python39\\site-packages\\fyers_apiv3\\FyersWebsocket\\data_ws.py\", line 1663, in <lambda>\n    on_error=lambda ws, msg: self.On_error(msg),\n  File \"C:\\Users\\Siddhi Waghmare\\AppData\\Roaming\\Python\\Python39\\site-packages\\fyers_apiv3\\FyersWebsocket\\data_ws.py\", line 1500, in On_error\n    self.OnError(message)\n  File \"c:\\Users\\Siddhi Waghmare\\Desktop\\Projects\\Trade_Executor\\backend\\webscoket_test.py\", line 21, in onerror\n    def onclose(message):\n  File \"C:\\Program Files\\Python39\\lib\\encodings\\cp1252.py\", line 19, in encode\n    return codecs.charmap_encode(input,self.errors,encoding_table)[0]\nUnicodeEncodeError: 'charmap' codec can't encode character '\\u274c' in position 0: character maps to <undefined>\n\nDuring handling of the above exception, another exception occurred:\n\nTraceback (most recent call last):\n  File \"C:\\Users\\Siddhi Waghmare\\AppData\\Roaming\\Python\\Python39\\site-packages\\websocket\\_app.py\", line 501, in run_forever\n    setSock()\n  File \"C:\\Users\\Siddhi Waghmare\\AppData\\Roaming\\Python\\Python39\\site-packages\\websocket\\_app.py\", line 430, in setSock\n    handleDisconnect(e, reconnecting)\n  File \"C:\\Users\\Siddhi Waghmare\\AppData\\Roaming\\Python\\Python39\\site-packages\\websocket\\_app.py\", line 481, in handleDisconnect\n    self._callback(self.on_error, e)\n  File \"C:\\Users\\Siddhi Waghmare\\AppData\\Roaming\\Python\\Python39\\site-packages\\websocket\\_app.py\", line 552, in _callback\n    self.on_error(self, e)\n  File \"C:\\Users\\Siddhi Waghmare\\AppData\\Roaming\\Python\\Python39\\site-packages\\fyers_apiv3\\FyersWebsocket\\data_ws.py\", line 1663, in <lambda>\n    on_error=lambda ws, msg: self.On_error(msg),\n  File \"C:\\Users\\Siddhi Waghmare\\AppData\\Roaming\\Python\\Python39\\site-packages\\fyers_apiv3\\FyersWebsocket\\data_ws.py\", line 1500, in On_error\n    self.OnError(message)\n  File \"c:\\Users\\Siddhi Waghmare\\Desktop\\Projects\\Trade_Executor\\backend\\webscoket_test.py\", line 21, in onerror\n    def onclose(message):\n  File \"C:\\Program Files\\Python39\\lib\\encodings\\cp1252.py\", line 19, in encode\n    return codecs.charmap_encode(input,self.errors,encoding_table)[0]\nUnicodeEncodeError: 'charmap' codec can't encode character '\\u274c' in position 0: character maps to <undefined>\n\nDuring handling of the above exception, another exception occurred:\n\nTraceback (most recent call last):\n  File \"C:\\Users\\Siddhi Waghmare\\AppData\\Roaming\\Python\\Python39\\site-packages\\fyers_apiv3\\FyersWebsocket\\data_ws.py\", line 1333, in __symbol_conversion\n    if symbol_value[3] != \"\":\nTypeError: 'NoneType' object is not subscriptable","exception_name":"TypeError"}
{"level":"ERROR","location":"[exception:108] fyers_logger","message":"HTTPSConnectionPool(host='api-t1.fyers.in', port=443): Max retries exceeded with url: /data/symbol-token (Caused by NewConnectionError('<urllib3.connection.HTTPSConnection object at 0x000001D155E19850>: Failed to establish a new connection: [Errno 11001] getaddrinfo failed'))","timestamp":"2025-06-25 19:49:19,136+0530","service":"FyersDataSocket","exception":"Traceback (most recent call last):\n  File \"C:\\Users\\Siddhi Waghmare\\AppData\\Roaming\\Python\\Python39\\site-packages\\websocket\\_app.py\", line 428, in setSock\n    dispatcher.read(self.sock.sock, read, check)\n  File \"C:\\Users\\Siddhi Waghmare\\AppData\\Roaming\\Python\\Python39\\site-packages\\websocket\\_app.py\", line 99, in read\n    if not read_callback():\n  File \"C:\\Users\\Siddhi Waghmare\\AppData\\Roaming\\Python\\Python39\\site-packages\\websocket\\_app.py\", line 437, in read\n    op_code, frame = self.sock.recv_data_frame(True)\n  File \"C:\\Users\\Siddhi Waghmare\\AppData\\Roaming\\Python\\Python39\\site-packages\\websocket\\_core.py\", line 406, in recv_data_frame\n    frame = self.recv_frame()\n  File \"C:\\Users\\Siddhi Waghmare\\AppData\\Roaming\\Python\\Python39\\site-packages\\websocket\\_core.py\", line 445, in recv_frame\n    return self.frame_buffer.recv_frame()\n  File \"C:\\Users\\Siddhi Waghmare\\AppData\\Roaming\\Python\\Python39\\site-packages\\websocket\\_abnf.py\", line 338, in recv_frame\n    self.recv_header()\n  File \"C:\\Users\\Siddhi Waghmare\\AppData\\Roaming\\Python\\Python39\\site-packages\\websocket\\_abnf.py\", line 294, in recv_header\n    header = self.recv_strict(2)\n  File \"C:\\Users\\Siddhi Waghmare\\AppData\\Roaming\\Python\\Python39\\site-packages\\websocket\\_abnf.py\", line 373, in recv_strict\n    bytes_ = self.recv(min(16384, shortage))\n  File \"C:\\Users\\Siddhi Waghmare\\AppData\\Roaming\\Python\\Python39\\site-packages\\websocket\\_core.py\", line 529, in _recv\n    return recv(self.sock, bufsize)\n  File \"C:\\Users\\Siddhi Waghmare\\AppData\\Roaming\\Python\\Python39\\site-packages\\websocket\\_socket.py\", line 108, in recv\n    bytes_ = _recv()\n  File \"C:\\Users\\Siddhi Waghmare\\AppData\\Roaming\\Python\\Python39\\site-packages\\websocket\\_socket.py\", line 87, in _recv\n    return sock.recv(bufsize)\n  File \"C:\\Program Files\\Python39\\lib\\ssl.py\", line 1226, in recv\n    return self.read(buflen)\n  File \"C:\\Program Files\\Python39\\lib\\ssl.py\", line 1101, in read\n    return self._sslobj.read(len)\nConnectionResetError: [WinError 10054] An existing connection was forcibly closed by the remote host\n\nDuring handling of the above exception, another exception occurred:\n\nTraceback (most recent call last):\n  File \"C:\\Users\\Siddhi Waghmare\\AppData\\Roaming\\Python\\Python39\\site-packages\\websocket\\_app.py\", line 547, in _callback\n    callback(self, *args)\n  File \"C:\\Users\\Siddhi Waghmare\\AppData\\Roaming\\Python\\Python39\\site-packages\\fyers_apiv3\\FyersWebsocket\\data_ws.py\", line 1663, in <lambda>\n    on_error=lambda ws, msg: self.On_error(msg),\n  File \"C:\\Users\\Siddhi Waghmare\\AppData\\Roaming\\Python\\Python39\\site-packages\\fyers_apiv3\\FyersWebsocket\\data_ws.py\", line 1500, in On_error\n    self.OnError(message)\n  File \"c:\\Users\\Siddhi Waghmare\\Desktop\\Projects\\Trade_Executor\\backend\\webscoket_test.py\", line 21, in onerror\n    def onclose(message):\n  File \"C:\\Program Files\\Python39\\lib\\encodings\\cp1252.py\", line 19, in encode\n    return codecs.charmap_encode(input,self.errors,encoding_table)[0]\nUnicodeEncodeError: 'charmap' codec can't encode character '\\u274c' in position 0: character maps to <undefined>\n\nDuring handling of the above exception, another exception occurred:\n\nTraceback (most recent call last):\n  File \"C:\\Users\\Siddhi Waghmare\\AppData\\Roaming\\Python\\Python39\\site-packages\\websocket\\_app.py\", line 501, in run_forever\n    setSock()\n  File \"C:\\Users\\Siddhi Waghmare\\AppData\\Roaming\\Python\\Python39\\site-packages\\websocket\\_app.py\", line 430, in setSock\n    handleDisconnect(e, reconnecting)\n  File \"C:\\Users\\Siddhi Waghmare\\AppData\\Roaming\\Python\\Python39\\site-packages\\websocket\\_app.py\", line 481, in handleDisconnect\n    self._callback(self.on_error, e)\n  File \"C:\\Users\\Siddhi Waghmare\\AppData\\Roaming\\Python\\Python39\\site-packages\\websocket\\_app.py\", line 552, in _callback\n    self.on_error(self, e)\n  File \"C:\\Users\\Siddhi Waghmare\\AppData\\Roaming\\Python\\Python39\\site-packages\\fyers_apiv3\\FyersWebsocket\\data_ws.py\", line 1663, in <lambda>\n    on_error=lambda ws, msg: self.On_error(msg),\n  File \"C:\\Users\\Siddhi Waghmare\\AppData\\Roaming\\Python\\Python39\\site-packages\\fyers_apiv3\\FyersWebsocket\\data_ws.py\", line 1500, in On_error\n    self.OnError(message)\n  File \"c:\\Users\\Siddhi Waghmare\\Desktop\\Projects\\Trade_Executor\\backend\\webscoket_test.py\", line 21, in onerror\n    def onclose(message):\n  File \"C:\\Program Files\\Python39\\lib\\encodings\\cp1252.py\", line 19, in encode\n    return codecs.charmap_encode(input,self.errors,encoding_table)[0]\nUnicodeEncodeError: 'charmap' codec can't encode character '\\u274c' in position 0: character maps to <undefined>\n\nDuring handling of the above exception, another exception occurred:\n\nTraceback (most recent call last):\n  File \"C:\\Users\\Siddhi Waghmare\\AppData\\Roaming\\Python\\Python39\\site-packages\\urllib3\\connection.py\", line 174, in _new_conn\n    conn = connection.create_connection(\n  File \"C:\\Users\\Siddhi Waghmare\\AppData\\Roaming\\Python\\Python39\\site-packages\\urllib3\\util\\connection.py\", line 72, in create_connection\n    for res in socket.getaddrinfo(host, port, family, socket.SOCK_STREAM):\n  File \"C:\\Program Files\\Python39\\lib\\socket.py\", line 953, in getaddrinfo\n    for res in _socket.getaddrinfo(host, port, family, type, proto, flags):\nsocket.gaierror: [Errno 11001] getaddrinfo failed\n\nDuring handling of the above exception, another exception occurred:\n\nTraceback (most recent call last):\n  File \"C:\\Users\\Siddhi Waghmare\\AppData\\Roaming\\Python\\Python39\\site-packages\\urllib3\\connectionpool.py\", line 716, in urlopen\n    httplib_response = self._make_request(\n  File \"C:\\Users\\Siddhi Waghmare\\AppData\\Roaming\\Python\\Python39\\site-packages\\urllib3\\connectionpool.py\", line 404, in _make_request\n    self._validate_conn(conn)\n  File \"C:\\Users\\Siddhi Waghmare\\AppData\\Roaming\\Python\\Python39\\site-packages\\urllib3\\connectionpool.py\", line 1061, in _validate_conn\n    conn.connect()\n  File \"C:\\Users\\Siddhi Waghmare\\AppData\\Roaming\\Python\\Python39\\site-packages\\urllib3\\connection.py\", line 363, in connect\n    self.sock = conn = self._new_conn()\n  File \"C:\\Users\\Siddhi Waghmare\\AppData\\Roaming\\Python\\Python39\\site-packages\\urllib3\\connection.py\", line 186, in _new_conn\n    raise NewConnectionError(\nurllib3.exceptions.NewConnectionError: <urllib3.connection.HTTPSConnection object at 0x000001D155E19850>: Failed to establish a new connection: [Errno 11001] getaddrinfo failed\n\nDuring handling of the above exception, another exception occurred:\n\nTraceback (most recent call last):\n  File \"C:\\Users\\Siddhi Waghmare\\AppData\\Roaming\\Python\\Python39\\site-packages\\requests\\adapters.py\", line 486, in send\n    resp = conn.urlopen(\n  File \"C:\\Users\\Siddhi Waghmare\\AppData\\Roaming\\Python\\Python39\\site-packages\\urllib3\\connectionpool.py\", line 802, in urlopen\n    retries = retries.increment(\n  File \"C:\\Users\\Siddhi Waghmare\\AppData\\Roaming\\Python\\Python39\\site-packages\\urllib3\\util\\retry.py\", line 594, in increment\n    raise MaxRetryError(_pool, url, error or ResponseError(cause))\nurllib3.exceptions.MaxRetryError: HTTPSConnectionPool(host='api-t1.fyers.in', port=443): Max retries exceeded with url: /data/symbol-token (Caused by NewConnectionError('<urllib3.connection.HTTPSConnection object at 0x000001D155E19850>: Failed to establish a new connection: [Errno 11001] getaddrinfo failed'))\n\nDuring handling of the above exception, another exception occurred:\n\nTraceback (most recent call last):\n  File \"C:\\Users\\Siddhi Waghmare\\AppData\\Roaming\\Python\\Python39\\site-packages\\fyers_apiv3\\FyersWebsocket\\data_ws.py\", line 63, in symbol_to_hsmtoken\n    response = requests.post(\n  File \"C:\\Users\\Siddhi Waghmare\\AppData\\Roaming\\Python\\Python39\\site-packages\\requests\\api.py\", line 115, in post\n    return request(\"post\", url, data=data, json=json, **kwargs)\n  File \"C:\\Users\\Siddhi Waghmare\\AppData\\Roaming\\Python\\Python39\\site-packages\\requests\\api.py\", line 59, in request\n    return session.request(method=method, url=url, **kwargs)\n  File \"C:\\Users\\Siddhi Waghmare\\AppData\\Roaming\\Python\\Python39\\site-packages\\requests\\sessions.py\", line 589, in request\n    resp = self.send(prep, **send_kwargs)\n  File \"C:\\Users\\Siddhi Waghmare\\AppData\\Roaming\\Python\\Python39\\site-packages\\requests\\sessions.py\", line 703, in send\n    r = adapter.send(request, **kwargs)\n  File \"C:\\Users\\Siddhi Waghmare\\AppData\\Roaming\\Python\\Python39\\site-packages\\requests\\adapters.py\", line 519, in send\n    raise ConnectionError(e, request=request)\nrequests.exceptions.ConnectionError: HTTPSConnectionPool(host='api-t1.fyers.in', port=443): Max retries exceeded with url: /data/symbol-token (Caused by NewConnectionError('<urllib3.connection.HTTPSConnection object at 0x000001D155E19850>: Failed to establish a new connection: [Errno 11001] getaddrinfo failed'))","exception_name":"ConnectionError"}
{"level":"ERROR","location":"[exception:108] fyers_logger","message":"'NoneType' object is not subscriptable","timestamp":"2025-06-25 19:49:19,148+0530","service":"FyersDataSocket","exception":"Traceback (most recent call last):\n  File \"C:\\Users\\Siddhi Waghmare\\AppData\\Roaming\\Python\\Python39\\site-packages\\websocket\\_app.py\", line 428, in setSock\n    dispatcher.read(self.sock.sock, read, check)\n  File \"C:\\Users\\Siddhi Waghmare\\AppData\\Roaming\\Python\\Python39\\site-packages\\websocket\\_app.py\", line 99, in read\n    if not read_callback():\n  File \"C:\\Users\\Siddhi Waghmare\\AppData\\Roaming\\Python\\Python39\\site-packages\\websocket\\_app.py\", line 437, in read\n    op_code, frame = self.sock.recv_data_frame(True)\n  File \"C:\\Users\\Siddhi Waghmare\\AppData\\Roaming\\Python\\Python39\\site-packages\\websocket\\_core.py\", line 406, in recv_data_frame\n    frame = self.recv_frame()\n  File \"C:\\Users\\Siddhi Waghmare\\AppData\\Roaming\\Python\\Python39\\site-packages\\websocket\\_core.py\", line 445, in recv_frame\n    return self.frame_buffer.recv_frame()\n  File \"C:\\Users\\Siddhi Waghmare\\AppData\\Roaming\\Python\\Python39\\site-packages\\websocket\\_abnf.py\", line 338, in recv_frame\n    self.recv_header()\n  File \"C:\\Users\\Siddhi Waghmare\\AppData\\Roaming\\Python\\Python39\\site-packages\\websocket\\_abnf.py\", line 294, in recv_header\n    header = self.recv_strict(2)\n  File \"C:\\Users\\Siddhi Waghmare\\AppData\\Roaming\\Python\\Python39\\site-packages\\websocket\\_abnf.py\", line 373, in recv_strict\n    bytes_ = self.recv(min(16384, shortage))\n  File \"C:\\Users\\Siddhi Waghmare\\AppData\\Roaming\\Python\\Python39\\site-packages\\websocket\\_core.py\", line 529, in _recv\n    return recv(self.sock, bufsize)\n  File \"C:\\Users\\Siddhi Waghmare\\AppData\\Roaming\\Python\\Python39\\site-packages\\websocket\\_socket.py\", line 108, in recv\n    bytes_ = _recv()\n  File \"C:\\Users\\Siddhi Waghmare\\AppData\\Roaming\\Python\\Python39\\site-packages\\websocket\\_socket.py\", line 87, in _recv\n    return sock.recv(bufsize)\n  File \"C:\\Program Files\\Python39\\lib\\ssl.py\", line 1226, in recv\n    return self.read(buflen)\n  File \"C:\\Program Files\\Python39\\lib\\ssl.py\", line 1101, in read\n    return self._sslobj.read(len)\nConnectionResetError: [WinError 10054] An existing connection was forcibly closed by the remote host\n\nDuring handling of the above exception, another exception occurred:\n\nTraceback (most recent call last):\n  File \"C:\\Users\\Siddhi Waghmare\\AppData\\Roaming\\Python\\Python39\\site-packages\\websocket\\_app.py\", line 547, in _callback\n    callback(self, *args)\n  File \"C:\\Users\\Siddhi Waghmare\\AppData\\Roaming\\Python\\Python39\\site-packages\\fyers_apiv3\\FyersWebsocket\\data_ws.py\", line 1663, in <lambda>\n    on_error=lambda ws, msg: self.On_error(msg),\n  File \"C:\\Users\\Siddhi Waghmare\\AppData\\Roaming\\Python\\Python39\\site-packages\\fyers_apiv3\\FyersWebsocket\\data_ws.py\", line 1500, in On_error\n    self.OnError(message)\n  File \"c:\\Users\\Siddhi Waghmare\\Desktop\\Projects\\Trade_Executor\\backend\\webscoket_test.py\", line 21, in onerror\n    def onclose(message):\n  File \"C:\\Program Files\\Python39\\lib\\encodings\\cp1252.py\", line 19, in encode\n    return codecs.charmap_encode(input,self.errors,encoding_table)[0]\nUnicodeEncodeError: 'charmap' codec can't encode character '\\u274c' in position 0: character maps to <undefined>\n\nDuring handling of the above exception, another exception occurred:\n\nTraceback (most recent call last):\n  File \"C:\\Users\\Siddhi Waghmare\\AppData\\Roaming\\Python\\Python39\\site-packages\\websocket\\_app.py\", line 501, in run_forever\n    setSock()\n  File \"C:\\Users\\Siddhi Waghmare\\AppData\\Roaming\\Python\\Python39\\site-packages\\websocket\\_app.py\", line 430, in setSock\n    handleDisconnect(e, reconnecting)\n  File \"C:\\Users\\Siddhi Waghmare\\AppData\\Roaming\\Python\\Python39\\site-packages\\websocket\\_app.py\", line 481, in handleDisconnect\n    self._callback(self.on_error, e)\n  File \"C:\\Users\\Siddhi Waghmare\\AppData\\Roaming\\Python\\Python39\\site-packages\\websocket\\_app.py\", line 552, in _callback\n    self.on_error(self, e)\n  File \"C:\\Users\\Siddhi Waghmare\\AppData\\Roaming\\Python\\Python39\\site-packages\\fyers_apiv3\\FyersWebsocket\\data_ws.py\", line 1663, in <lambda>\n    on_error=lambda ws, msg: self.On_error(msg),\n  File \"C:\\Users\\Siddhi Waghmare\\AppData\\Roaming\\Python\\Python39\\site-packages\\fyers_apiv3\\FyersWebsocket\\data_ws.py\", line 1500, in On_error\n    self.OnError(message)\n  File \"c:\\Users\\Siddhi Waghmare\\Desktop\\Projects\\Trade_Executor\\backend\\webscoket_test.py\", line 21, in onerror\n    def onclose(message):\n  File \"C:\\Program Files\\Python39\\lib\\encodings\\cp1252.py\", line 19, in encode\n    return codecs.charmap_encode(input,self.errors,encoding_table)[0]\nUnicodeEncodeError: 'charmap' codec can't encode character '\\u274c' in position 0: character maps to <undefined>\n\nDuring handling of the above exception, another exception occurred:\n\nTraceback (most recent call last):\n  File \"C:\\Users\\Siddhi Waghmare\\AppData\\Roaming\\Python\\Python39\\site-packages\\fyers_apiv3\\FyersWebsocket\\data_ws.py\", line 1333, in __symbol_conversion\n    if symbol_value[3] != \"\":\nTypeError: 'NoneType' object is not subscriptable","exception_name":"TypeError"}
{"level":"ERROR","location":"[exception:108] fyers_logger","message":"HTTPSConnectionPool(host='api-t1.fyers.in', port=443): Max retries exceeded with url: /data/symbol-token (Caused by NewConnectionError('<urllib3.connection.HTTPSConnection object at 0x000001D155E19610>: Failed to establish a new connection: [Errno 11001] getaddrinfo failed'))","timestamp":"2025-06-25 19:49:24,141+0530","service":"FyersDataSocket","exception":"Traceback (most recent call last):\n  File \"C:\\Users\\Siddhi Waghmare\\AppData\\Roaming\\Python\\Python39\\site-packages\\websocket\\_http.py\", line 155, in _get_addrinfo_list\n    addrinfo_list = socket.getaddrinfo(\n  File \"C:\\Program Files\\Python39\\lib\\socket.py\", line 953, in getaddrinfo\n    for res in _socket.getaddrinfo(host, port, family, type, proto, flags):\nsocket.gaierror: [Errno 11001] getaddrinfo failed\n\nDuring handling of the above exception, another exception occurred:\n\nTraceback (most recent call last):\n  File \"C:\\Users\\Siddhi Waghmare\\AppData\\Roaming\\Python\\Python39\\site-packages\\websocket\\_app.py\", line 412, in setSock\n    self.sock.connect(\n  File \"C:\\Users\\Siddhi Waghmare\\AppData\\Roaming\\Python\\Python39\\site-packages\\websocket\\_core.py\", line 249, in connect\n    self.sock, addrs = connect(url, self.sock_opt, proxy_info(**options),\n  File \"C:\\Users\\Siddhi Waghmare\\AppData\\Roaming\\Python\\Python39\\site-packages\\websocket\\_http.py\", line 122, in connect\n    addrinfo_list, need_tunnel, auth = _get_addrinfo_list(\n  File \"C:\\Users\\Siddhi Waghmare\\AppData\\Roaming\\Python\\Python39\\site-packages\\websocket\\_http.py\", line 167, in _get_addrinfo_list\n    raise WebSocketAddressException(e)\nwebsocket._exceptions.WebSocketAddressException: [Errno 11001] getaddrinfo failed\n\nDuring handling of the above exception, another exception occurred:\n\nTraceback (most recent call last):\n  File \"C:\\Users\\Siddhi Waghmare\\AppData\\Roaming\\Python\\Python39\\site-packages\\websocket\\_app.py\", line 547, in _callback\n    callback(self, *args)\n  File \"C:\\Users\\Siddhi Waghmare\\AppData\\Roaming\\Python\\Python39\\site-packages\\fyers_apiv3\\FyersWebsocket\\data_ws.py\", line 1663, in <lambda>\n    on_error=lambda ws, msg: self.On_error(msg),\n  File \"C:\\Users\\Siddhi Waghmare\\AppData\\Roaming\\Python\\Python39\\site-packages\\fyers_apiv3\\FyersWebsocket\\data_ws.py\", line 1500, in On_error\n    self.OnError(message)\n  File \"c:\\Users\\Siddhi Waghmare\\Desktop\\Projects\\Trade_Executor\\backend\\webscoket_test.py\", line 21, in onerror\n    def onclose(message):\n  File \"C:\\Program Files\\Python39\\lib\\encodings\\cp1252.py\", line 19, in encode\n    return codecs.charmap_encode(input,self.errors,encoding_table)[0]\nUnicodeEncodeError: 'charmap' codec can't encode character '\\u274c' in position 0: character maps to <undefined>\n\nDuring handling of the above exception, another exception occurred:\n\nTraceback (most recent call last):\n  File \"C:\\Users\\Siddhi Waghmare\\AppData\\Roaming\\Python\\Python39\\site-packages\\websocket\\_app.py\", line 501, in run_forever\n    setSock()\n  File \"C:\\Users\\Siddhi Waghmare\\AppData\\Roaming\\Python\\Python39\\site-packages\\websocket\\_app.py\", line 430, in setSock\n    handleDisconnect(e, reconnecting)\n  File \"C:\\Users\\Siddhi Waghmare\\AppData\\Roaming\\Python\\Python39\\site-packages\\websocket\\_app.py\", line 481, in handleDisconnect\n    self._callback(self.on_error, e)\n  File \"C:\\Users\\Siddhi Waghmare\\AppData\\Roaming\\Python\\Python39\\site-packages\\websocket\\_app.py\", line 552, in _callback\n    self.on_error(self, e)\n  File \"C:\\Users\\Siddhi Waghmare\\AppData\\Roaming\\Python\\Python39\\site-packages\\fyers_apiv3\\FyersWebsocket\\data_ws.py\", line 1663, in <lambda>\n    on_error=lambda ws, msg: self.On_error(msg),\n  File \"C:\\Users\\Siddhi Waghmare\\AppData\\Roaming\\Python\\Python39\\site-packages\\fyers_apiv3\\FyersWebsocket\\data_ws.py\", line 1500, in On_error\n    self.OnError(message)\n  File \"c:\\Users\\Siddhi Waghmare\\Desktop\\Projects\\Trade_Executor\\backend\\webscoket_test.py\", line 21, in onerror\n    def onclose(message):\n  File \"C:\\Program Files\\Python39\\lib\\encodings\\cp1252.py\", line 19, in encode\n    return codecs.charmap_encode(input,self.errors,encoding_table)[0]\nUnicodeEncodeError: 'charmap' codec can't encode character '\\u274c' in position 0: character maps to <undefined>\n\nDuring handling of the above exception, another exception occurred:\n\nTraceback (most recent call last):\n  File \"C:\\Users\\Siddhi Waghmare\\AppData\\Roaming\\Python\\Python39\\site-packages\\urllib3\\connection.py\", line 174, in _new_conn\n    conn = connection.create_connection(\n  File \"C:\\Users\\Siddhi Waghmare\\AppData\\Roaming\\Python\\Python39\\site-packages\\urllib3\\util\\connection.py\", line 72, in create_connection\n    for res in socket.getaddrinfo(host, port, family, socket.SOCK_STREAM):\n  File \"C:\\Program Files\\Python39\\lib\\socket.py\", line 953, in getaddrinfo\n    for res in _socket.getaddrinfo(host, port, family, type, proto, flags):\nsocket.gaierror: [Errno 11001] getaddrinfo failed\n\nDuring handling of the above exception, another exception occurred:\n\nTraceback (most recent call last):\n  File \"C:\\Users\\Siddhi Waghmare\\AppData\\Roaming\\Python\\Python39\\site-packages\\urllib3\\connectionpool.py\", line 716, in urlopen\n    httplib_response = self._make_request(\n  File \"C:\\Users\\Siddhi Waghmare\\AppData\\Roaming\\Python\\Python39\\site-packages\\urllib3\\connectionpool.py\", line 404, in _make_request\n    self._validate_conn(conn)\n  File \"C:\\Users\\Siddhi Waghmare\\AppData\\Roaming\\Python\\Python39\\site-packages\\urllib3\\connectionpool.py\", line 1061, in _validate_conn\n    conn.connect()\n  File \"C:\\Users\\Siddhi Waghmare\\AppData\\Roaming\\Python\\Python39\\site-packages\\urllib3\\connection.py\", line 363, in connect\n    self.sock = conn = self._new_conn()\n  File \"C:\\Users\\Siddhi Waghmare\\AppData\\Roaming\\Python\\Python39\\site-packages\\urllib3\\connection.py\", line 186, in _new_conn\n    raise NewConnectionError(\nurllib3.exceptions.NewConnectionError: <urllib3.connection.HTTPSConnection object at 0x000001D155E19610>: Failed to establish a new connection: [Errno 11001] getaddrinfo failed\n\nDuring handling of the above exception, another exception occurred:\n\nTraceback (most recent call last):\n  File \"C:\\Users\\Siddhi Waghmare\\AppData\\Roaming\\Python\\Python39\\site-packages\\requests\\adapters.py\", line 486, in send\n    resp = conn.urlopen(\n  File \"C:\\Users\\Siddhi Waghmare\\AppData\\Roaming\\Python\\Python39\\site-packages\\urllib3\\connectionpool.py\", line 802, in urlopen\n    retries = retries.increment(\n  File \"C:\\Users\\Siddhi Waghmare\\AppData\\Roaming\\Python\\Python39\\site-packages\\urllib3\\util\\retry.py\", line 594, in increment\n    raise MaxRetryError(_pool, url, error or ResponseError(cause))\nurllib3.exceptions.MaxRetryError: HTTPSConnectionPool(host='api-t1.fyers.in', port=443): Max retries exceeded with url: /data/symbol-token (Caused by NewConnectionError('<urllib3.connection.HTTPSConnection object at 0x000001D155E19610>: Failed to establish a new connection: [Errno 11001] getaddrinfo failed'))\n\nDuring handling of the above exception, another exception occurred:\n\nTraceback (most recent call last):\n  File \"C:\\Users\\Siddhi Waghmare\\AppData\\Roaming\\Python\\Python39\\site-packages\\fyers_apiv3\\FyersWebsocket\\data_ws.py\", line 63, in symbol_to_hsmtoken\n    response = requests.post(\n  File \"C:\\Users\\Siddhi Waghmare\\AppData\\Roaming\\Python\\Python39\\site-packages\\requests\\api.py\", line 115, in post\n    return request(\"post\", url, data=data, json=json, **kwargs)\n  File \"C:\\Users\\Siddhi Waghmare\\AppData\\Roaming\\Python\\Python39\\site-packages\\requests\\api.py\", line 59, in request\n    return session.request(method=method, url=url, **kwargs)\n  File \"C:\\Users\\Siddhi Waghmare\\AppData\\Roaming\\Python\\Python39\\site-packages\\requests\\sessions.py\", line 589, in request\n    resp = self.send(prep, **send_kwargs)\n  File \"C:\\Users\\Siddhi Waghmare\\AppData\\Roaming\\Python\\Python39\\site-packages\\requests\\sessions.py\", line 703, in send\n    r = adapter.send(request, **kwargs)\n  File \"C:\\Users\\Siddhi Waghmare\\AppData\\Roaming\\Python\\Python39\\site-packages\\requests\\adapters.py\", line 519, in send\n    raise ConnectionError(e, request=request)\nrequests.exceptions.ConnectionError: HTTPSConnectionPool(host='api-t1.fyers.in', port=443): Max retries exceeded with url: /data/symbol-token (Caused by NewConnectionError('<urllib3.connection.HTTPSConnection object at 0x000001D155E19610>: Failed to establish a new connection: [Errno 11001] getaddrinfo failed'))","exception_name":"ConnectionError"}
{"level":"ERROR","location":"[exception:108] fyers_logger","message":"'NoneType' object is not subscriptable","timestamp":"2025-06-25 19:49:24,143+0530","service":"FyersDataSocket","exception":"Traceback (most recent call last):\n  File \"C:\\Users\\Siddhi Waghmare\\AppData\\Roaming\\Python\\Python39\\site-packages\\websocket\\_http.py\", line 155, in _get_addrinfo_list\n    addrinfo_list = socket.getaddrinfo(\n  File \"C:\\Program Files\\Python39\\lib\\socket.py\", line 953, in getaddrinfo\n    for res in _socket.getaddrinfo(host, port, family, type, proto, flags):\nsocket.gaierror: [Errno 11001] getaddrinfo failed\n\nDuring handling of the above exception, another exception occurred:\n\nTraceback (most recent call last):\n  File \"C:\\Users\\Siddhi Waghmare\\AppData\\Roaming\\Python\\Python39\\site-packages\\websocket\\_app.py\", line 412, in setSock\n    self.sock.connect(\n  File \"C:\\Users\\Siddhi Waghmare\\AppData\\Roaming\\Python\\Python39\\site-packages\\websocket\\_core.py\", line 249, in connect\n    self.sock, addrs = connect(url, self.sock_opt, proxy_info(**options),\n  File \"C:\\Users\\Siddhi Waghmare\\AppData\\Roaming\\Python\\Python39\\site-packages\\websocket\\_http.py\", line 122, in connect\n    addrinfo_list, need_tunnel, auth = _get_addrinfo_list(\n  File \"C:\\Users\\Siddhi Waghmare\\AppData\\Roaming\\Python\\Python39\\site-packages\\websocket\\_http.py\", line 167, in _get_addrinfo_list\n    raise WebSocketAddressException(e)\nwebsocket._exceptions.WebSocketAddressException: [Errno 11001] getaddrinfo failed\n\nDuring handling of the above exception, another exception occurred:\n\nTraceback (most recent call last):\n  File \"C:\\Users\\Siddhi Waghmare\\AppData\\Roaming\\Python\\Python39\\site-packages\\websocket\\_app.py\", line 547, in _callback\n    callback(self, *args)\n  File \"C:\\Users\\Siddhi Waghmare\\AppData\\Roaming\\Python\\Python39\\site-packages\\fyers_apiv3\\FyersWebsocket\\data_ws.py\", line 1663, in <lambda>\n    on_error=lambda ws, msg: self.On_error(msg),\n  File \"C:\\Users\\Siddhi Waghmare\\AppData\\Roaming\\Python\\Python39\\site-packages\\fyers_apiv3\\FyersWebsocket\\data_ws.py\", line 1500, in On_error\n    self.OnError(message)\n  File \"c:\\Users\\Siddhi Waghmare\\Desktop\\Projects\\Trade_Executor\\backend\\webscoket_test.py\", line 21, in onerror\n    def onclose(message):\n  File \"C:\\Program Files\\Python39\\lib\\encodings\\cp1252.py\", line 19, in encode\n    return codecs.charmap_encode(input,self.errors,encoding_table)[0]\nUnicodeEncodeError: 'charmap' codec can't encode character '\\u274c' in position 0: character maps to <undefined>\n\nDuring handling of the above exception, another exception occurred:\n\nTraceback (most recent call last):\n  File \"C:\\Users\\Siddhi Waghmare\\AppData\\Roaming\\Python\\Python39\\site-packages\\websocket\\_app.py\", line 501, in run_forever\n    setSock()\n  File \"C:\\Users\\Siddhi Waghmare\\AppData\\Roaming\\Python\\Python39\\site-packages\\websocket\\_app.py\", line 430, in setSock\n    handleDisconnect(e, reconnecting)\n  File \"C:\\Users\\Siddhi Waghmare\\AppData\\Roaming\\Python\\Python39\\site-packages\\websocket\\_app.py\", line 481, in handleDisconnect\n    self._callback(self.on_error, e)\n  File \"C:\\Users\\Siddhi Waghmare\\AppData\\Roaming\\Python\\Python39\\site-packages\\websocket\\_app.py\", line 552, in _callback\n    self.on_error(self, e)\n  File \"C:\\Users\\Siddhi Waghmare\\AppData\\Roaming\\Python\\Python39\\site-packages\\fyers_apiv3\\FyersWebsocket\\data_ws.py\", line 1663, in <lambda>\n    on_error=lambda ws, msg: self.On_error(msg),\n  File \"C:\\Users\\Siddhi Waghmare\\AppData\\Roaming\\Python\\Python39\\site-packages\\fyers_apiv3\\FyersWebsocket\\data_ws.py\", line 1500, in On_error\n    self.OnError(message)\n  File \"c:\\Users\\Siddhi Waghmare\\Desktop\\Projects\\Trade_Executor\\backend\\webscoket_test.py\", line 21, in onerror\n    def onclose(message):\n  File \"C:\\Program Files\\Python39\\lib\\encodings\\cp1252.py\", line 19, in encode\n    return codecs.charmap_encode(input,self.errors,encoding_table)[0]\nUnicodeEncodeError: 'charmap' codec can't encode character '\\u274c' in position 0: character maps to <undefined>\n\nDuring handling of the above exception, another exception occurred:\n\nTraceback (most recent call last):\n  File \"C:\\Users\\Siddhi Waghmare\\AppData\\Roaming\\Python\\Python39\\site-packages\\fyers_apiv3\\FyersWebsocket\\data_ws.py\", line 1333, in __symbol_conversion\n    if symbol_value[3] != \"\":\nTypeError: 'NoneType' object is not subscriptable","exception_name":"TypeError"}
{"level":"ERROR","location":"[exception:108] fyers_logger","message":"HTTPSConnectionPool(host='api-t1.fyers.in', port=443): Max retries exceeded with url: /data/symbol-token (Caused by NewConnectionError('<urllib3.connection.HTTPSConnection object at 0x000001D155E1A700>: Failed to establish a new connection: [Errno 11001] getaddrinfo failed'))","timestamp":"2025-06-25 19:49:29,148+0530","service":"FyersDataSocket","exception":"Traceback (most recent call last):\n  File \"C:\\Users\\Siddhi Waghmare\\AppData\\Roaming\\Python\\Python39\\site-packages\\websocket\\_http.py\", line 155, in _get_addrinfo_list\n    addrinfo_list = socket.getaddrinfo(\n  File \"C:\\Program Files\\Python39\\lib\\socket.py\", line 953, in getaddrinfo\n    for res in _socket.getaddrinfo(host, port, family, type, proto, flags):\nsocket.gaierror: [Errno 11001] getaddrinfo failed\n\nDuring handling of the above exception, another exception occurred:\n\nTraceback (most recent call last):\n  File \"C:\\Users\\Siddhi Waghmare\\AppData\\Roaming\\Python\\Python39\\site-packages\\websocket\\_app.py\", line 412, in setSock\n    self.sock.connect(\n  File \"C:\\Users\\Siddhi Waghmare\\AppData\\Roaming\\Python\\Python39\\site-packages\\websocket\\_core.py\", line 249, in connect\n    self.sock, addrs = connect(url, self.sock_opt, proxy_info(**options),\n  File \"C:\\Users\\Siddhi Waghmare\\AppData\\Roaming\\Python\\Python39\\site-packages\\websocket\\_http.py\", line 122, in connect\n    addrinfo_list, need_tunnel, auth = _get_addrinfo_list(\n  File \"C:\\Users\\Siddhi Waghmare\\AppData\\Roaming\\Python\\Python39\\site-packages\\websocket\\_http.py\", line 167, in _get_addrinfo_list\n    raise WebSocketAddressException(e)\nwebsocket._exceptions.WebSocketAddressException: [Errno 11001] getaddrinfo failed\n\nDuring handling of the above exception, another exception occurred:\n\nTraceback (most recent call last):\n  File \"C:\\Users\\Siddhi Waghmare\\AppData\\Roaming\\Python\\Python39\\site-packages\\websocket\\_app.py\", line 547, in _callback\n    callback(self, *args)\n  File \"C:\\Users\\Siddhi Waghmare\\AppData\\Roaming\\Python\\Python39\\site-packages\\fyers_apiv3\\FyersWebsocket\\data_ws.py\", line 1663, in <lambda>\n    on_error=lambda ws, msg: self.On_error(msg),\n  File \"C:\\Users\\Siddhi Waghmare\\AppData\\Roaming\\Python\\Python39\\site-packages\\fyers_apiv3\\FyersWebsocket\\data_ws.py\", line 1500, in On_error\n    self.OnError(message)\n  File \"c:\\Users\\Siddhi Waghmare\\Desktop\\Projects\\Trade_Executor\\backend\\webscoket_test.py\", line 21, in onerror\n    def onclose(message):\n  File \"C:\\Program Files\\Python39\\lib\\encodings\\cp1252.py\", line 19, in encode\n    return codecs.charmap_encode(input,self.errors,encoding_table)[0]\nUnicodeEncodeError: 'charmap' codec can't encode character '\\u274c' in position 0: character maps to <undefined>\n\nDuring handling of the above exception, another exception occurred:\n\nTraceback (most recent call last):\n  File \"C:\\Users\\Siddhi Waghmare\\AppData\\Roaming\\Python\\Python39\\site-packages\\websocket\\_app.py\", line 501, in run_forever\n    setSock()\n  File \"C:\\Users\\Siddhi Waghmare\\AppData\\Roaming\\Python\\Python39\\site-packages\\websocket\\_app.py\", line 430, in setSock\n    handleDisconnect(e, reconnecting)\n  File \"C:\\Users\\Siddhi Waghmare\\AppData\\Roaming\\Python\\Python39\\site-packages\\websocket\\_app.py\", line 481, in handleDisconnect\n    self._callback(self.on_error, e)\n  File \"C:\\Users\\Siddhi Waghmare\\AppData\\Roaming\\Python\\Python39\\site-packages\\websocket\\_app.py\", line 552, in _callback\n    self.on_error(self, e)\n  File \"C:\\Users\\Siddhi Waghmare\\AppData\\Roaming\\Python\\Python39\\site-packages\\fyers_apiv3\\FyersWebsocket\\data_ws.py\", line 1663, in <lambda>\n    on_error=lambda ws, msg: self.On_error(msg),\n  File \"C:\\Users\\Siddhi Waghmare\\AppData\\Roaming\\Python\\Python39\\site-packages\\fyers_apiv3\\FyersWebsocket\\data_ws.py\", line 1500, in On_error\n    self.OnError(message)\n  File \"c:\\Users\\Siddhi Waghmare\\Desktop\\Projects\\Trade_Executor\\backend\\webscoket_test.py\", line 21, in onerror\n    def onclose(message):\n  File \"C:\\Program Files\\Python39\\lib\\encodings\\cp1252.py\", line 19, in encode\n    return codecs.charmap_encode(input,self.errors,encoding_table)[0]\nUnicodeEncodeError: 'charmap' codec can't encode character '\\u274c' in position 0: character maps to <undefined>\n\nDuring handling of the above exception, another exception occurred:\n\nTraceback (most recent call last):\n  File \"C:\\Users\\Siddhi Waghmare\\AppData\\Roaming\\Python\\Python39\\site-packages\\urllib3\\connection.py\", line 174, in _new_conn\n    conn = connection.create_connection(\n  File \"C:\\Users\\Siddhi Waghmare\\AppData\\Roaming\\Python\\Python39\\site-packages\\urllib3\\util\\connection.py\", line 72, in create_connection\n    for res in socket.getaddrinfo(host, port, family, socket.SOCK_STREAM):\n  File \"C:\\Program Files\\Python39\\lib\\socket.py\", line 953, in getaddrinfo\n    for res in _socket.getaddrinfo(host, port, family, type, proto, flags):\nsocket.gaierror: [Errno 11001] getaddrinfo failed\n\nDuring handling of the above exception, another exception occurred:\n\nTraceback (most recent call last):\n  File \"C:\\Users\\Siddhi Waghmare\\AppData\\Roaming\\Python\\Python39\\site-packages\\urllib3\\connectionpool.py\", line 716, in urlopen\n    httplib_response = self._make_request(\n  File \"C:\\Users\\Siddhi Waghmare\\AppData\\Roaming\\Python\\Python39\\site-packages\\urllib3\\connectionpool.py\", line 404, in _make_request\n    self._validate_conn(conn)\n  File \"C:\\Users\\Siddhi Waghmare\\AppData\\Roaming\\Python\\Python39\\site-packages\\urllib3\\connectionpool.py\", line 1061, in _validate_conn\n    conn.connect()\n  File \"C:\\Users\\Siddhi Waghmare\\AppData\\Roaming\\Python\\Python39\\site-packages\\urllib3\\connection.py\", line 363, in connect\n    self.sock = conn = self._new_conn()\n  File \"C:\\Users\\Siddhi Waghmare\\AppData\\Roaming\\Python\\Python39\\site-packages\\urllib3\\connection.py\", line 186, in _new_conn\n    raise NewConnectionError(\nurllib3.exceptions.NewConnectionError: <urllib3.connection.HTTPSConnection object at 0x000001D155E1A700>: Failed to establish a new connection: [Errno 11001] getaddrinfo failed\n\nDuring handling of the above exception, another exception occurred:\n\nTraceback (most recent call last):\n  File \"C:\\Users\\Siddhi Waghmare\\AppData\\Roaming\\Python\\Python39\\site-packages\\requests\\adapters.py\", line 486, in send\n    resp = conn.urlopen(\n  File \"C:\\Users\\Siddhi Waghmare\\AppData\\Roaming\\Python\\Python39\\site-packages\\urllib3\\connectionpool.py\", line 802, in urlopen\n    retries = retries.increment(\n  File \"C:\\Users\\Siddhi Waghmare\\AppData\\Roaming\\Python\\Python39\\site-packages\\urllib3\\util\\retry.py\", line 594, in increment\n    raise MaxRetryError(_pool, url, error or ResponseError(cause))\nurllib3.exceptions.MaxRetryError: HTTPSConnectionPool(host='api-t1.fyers.in', port=443): Max retries exceeded with url: /data/symbol-token (Caused by NewConnectionError('<urllib3.connection.HTTPSConnection object at 0x000001D155E1A700>: Failed to establish a new connection: [Errno 11001] getaddrinfo failed'))\n\nDuring handling of the above exception, another exception occurred:\n\nTraceback (most recent call last):\n  File \"C:\\Users\\Siddhi Waghmare\\AppData\\Roaming\\Python\\Python39\\site-packages\\fyers_apiv3\\FyersWebsocket\\data_ws.py\", line 63, in symbol_to_hsmtoken\n    response = requests.post(\n  File \"C:\\Users\\Siddhi Waghmare\\AppData\\Roaming\\Python\\Python39\\site-packages\\requests\\api.py\", line 115, in post\n    return request(\"post\", url, data=data, json=json, **kwargs)\n  File \"C:\\Users\\Siddhi Waghmare\\AppData\\Roaming\\Python\\Python39\\site-packages\\requests\\api.py\", line 59, in request\n    return session.request(method=method, url=url, **kwargs)\n  File \"C:\\Users\\Siddhi Waghmare\\AppData\\Roaming\\Python\\Python39\\site-packages\\requests\\sessions.py\", line 589, in request\n    resp = self.send(prep, **send_kwargs)\n  File \"C:\\Users\\Siddhi Waghmare\\AppData\\Roaming\\Python\\Python39\\site-packages\\requests\\sessions.py\", line 703, in send\n    r = adapter.send(request, **kwargs)\n  File \"C:\\Users\\Siddhi Waghmare\\AppData\\Roaming\\Python\\Python39\\site-packages\\requests\\adapters.py\", line 519, in send\n    raise ConnectionError(e, request=request)\nrequests.exceptions.ConnectionError: HTTPSConnectionPool(host='api-t1.fyers.in', port=443): Max retries exceeded with url: /data/symbol-token (Caused by NewConnectionError('<urllib3.connection.HTTPSConnection object at 0x000001D155E1A700>: Failed to establish a new connection: [Errno 11001] getaddrinfo failed'))","exception_name":"ConnectionError"}
{"level":"ERROR","location":"[exception:108] fyers_logger","message":"'NoneType' object is not subscriptable","timestamp":"2025-06-25 19:49:29,148+0530","service":"FyersDataSocket","exception":"Traceback (most recent call last):\n  File \"C:\\Users\\Siddhi Waghmare\\AppData\\Roaming\\Python\\Python39\\site-packages\\websocket\\_http.py\", line 155, in _get_addrinfo_list\n    addrinfo_list = socket.getaddrinfo(\n  File \"C:\\Program Files\\Python39\\lib\\socket.py\", line 953, in getaddrinfo\n    for res in _socket.getaddrinfo(host, port, family, type, proto, flags):\nsocket.gaierror: [Errno 11001] getaddrinfo failed\n\nDuring handling of the above exception, another exception occurred:\n\nTraceback (most recent call last):\n  File \"C:\\Users\\Siddhi Waghmare\\AppData\\Roaming\\Python\\Python39\\site-packages\\websocket\\_app.py\", line 412, in setSock\n    self.sock.connect(\n  File \"C:\\Users\\Siddhi Waghmare\\AppData\\Roaming\\Python\\Python39\\site-packages\\websocket\\_core.py\", line 249, in connect\n    self.sock, addrs = connect(url, self.sock_opt, proxy_info(**options),\n  File \"C:\\Users\\Siddhi Waghmare\\AppData\\Roaming\\Python\\Python39\\site-packages\\websocket\\_http.py\", line 122, in connect\n    addrinfo_list, need_tunnel, auth = _get_addrinfo_list(\n  File \"C:\\Users\\Siddhi Waghmare\\AppData\\Roaming\\Python\\Python39\\site-packages\\websocket\\_http.py\", line 167, in _get_addrinfo_list\n    raise WebSocketAddressException(e)\nwebsocket._exceptions.WebSocketAddressException: [Errno 11001] getaddrinfo failed\n\nDuring handling of the above exception, another exception occurred:\n\nTraceback (most recent call last):\n  File \"C:\\Users\\Siddhi Waghmare\\AppData\\Roaming\\Python\\Python39\\site-packages\\websocket\\_app.py\", line 547, in _callback\n    callback(self, *args)\n  File \"C:\\Users\\Siddhi Waghmare\\AppData\\Roaming\\Python\\Python39\\site-packages\\fyers_apiv3\\FyersWebsocket\\data_ws.py\", line 1663, in <lambda>\n    on_error=lambda ws, msg: self.On_error(msg),\n  File \"C:\\Users\\Siddhi Waghmare\\AppData\\Roaming\\Python\\Python39\\site-packages\\fyers_apiv3\\FyersWebsocket\\data_ws.py\", line 1500, in On_error\n    self.OnError(message)\n  File \"c:\\Users\\Siddhi Waghmare\\Desktop\\Projects\\Trade_Executor\\backend\\webscoket_test.py\", line 21, in onerror\n    def onclose(message):\n  File \"C:\\Program Files\\Python39\\lib\\encodings\\cp1252.py\", line 19, in encode\n    return codecs.charmap_encode(input,self.errors,encoding_table)[0]\nUnicodeEncodeError: 'charmap' codec can't encode character '\\u274c' in position 0: character maps to <undefined>\n\nDuring handling of the above exception, another exception occurred:\n\nTraceback (most recent call last):\n  File \"C:\\Users\\Siddhi Waghmare\\AppData\\Roaming\\Python\\Python39\\site-packages\\websocket\\_app.py\", line 501, in run_forever\n    setSock()\n  File \"C:\\Users\\Siddhi Waghmare\\AppData\\Roaming\\Python\\Python39\\site-packages\\websocket\\_app.py\", line 430, in setSock\n    handleDisconnect(e, reconnecting)\n  File \"C:\\Users\\Siddhi Waghmare\\AppData\\Roaming\\Python\\Python39\\site-packages\\websocket\\_app.py\", line 481, in handleDisconnect\n    self._callback(self.on_error, e)\n  File \"C:\\Users\\Siddhi Waghmare\\AppData\\Roaming\\Python\\Python39\\site-packages\\websocket\\_app.py\", line 552, in _callback\n    self.on_error(self, e)\n  File \"C:\\Users\\Siddhi Waghmare\\AppData\\Roaming\\Python\\Python39\\site-packages\\fyers_apiv3\\FyersWebsocket\\data_ws.py\", line 1663, in <lambda>\n    on_error=lambda ws, msg: self.On_error(msg),\n  File \"C:\\Users\\Siddhi Waghmare\\AppData\\Roaming\\Python\\Python39\\site-packages\\fyers_apiv3\\FyersWebsocket\\data_ws.py\", line 1500, in On_error\n    self.OnError(message)\n  File \"c:\\Users\\Siddhi Waghmare\\Desktop\\Projects\\Trade_Executor\\backend\\webscoket_test.py\", line 21, in onerror\n    def onclose(message):\n  File \"C:\\Program Files\\Python39\\lib\\encodings\\cp1252.py\", line 19, in encode\n    return codecs.charmap_encode(input,self.errors,encoding_table)[0]\nUnicodeEncodeError: 'charmap' codec can't encode character '\\u274c' in position 0: character maps to <undefined>\n\nDuring handling of the above exception, another exception occurred:\n\nTraceback (most recent call last):\n  File \"C:\\Users\\Siddhi Waghmare\\AppData\\Roaming\\Python\\Python39\\site-packages\\fyers_apiv3\\FyersWebsocket\\data_ws.py\", line 1333, in __symbol_conversion\n    if symbol_value[3] != \"\":\nTypeError: 'NoneType' object is not subscriptable","exception_name":"TypeError"}
{"level":"ERROR","location":"[exception:108] fyers_logger","message":"HTTPSConnectionPool(host='api-t1.fyers.in', port=443): Max retries exceeded with url: /data/symbol-token (Caused by NewConnectionError('<urllib3.connection.HTTPSConnection object at 0x000001D155E0B070>: Failed to establish a new connection: [Errno 11001] getaddrinfo failed'))","timestamp":"2025-06-25 19:49:34,152+0530","service":"FyersDataSocket","exception":"Traceback (most recent call last):\n  File \"C:\\Users\\Siddhi Waghmare\\AppData\\Roaming\\Python\\Python39\\site-packages\\websocket\\_http.py\", line 155, in _get_addrinfo_list\n    addrinfo_list = socket.getaddrinfo(\n  File \"C:\\Program Files\\Python39\\lib\\socket.py\", line 953, in getaddrinfo\n    for res in _socket.getaddrinfo(host, port, family, type, proto, flags):\nsocket.gaierror: [Errno 11001] getaddrinfo failed\n\nDuring handling of the above exception, another exception occurred:\n\nTraceback (most recent call last):\n  File \"C:\\Users\\Siddhi Waghmare\\AppData\\Roaming\\Python\\Python39\\site-packages\\websocket\\_app.py\", line 412, in setSock\n    self.sock.connect(\n  File \"C:\\Users\\Siddhi Waghmare\\AppData\\Roaming\\Python\\Python39\\site-packages\\websocket\\_core.py\", line 249, in connect\n    self.sock, addrs = connect(url, self.sock_opt, proxy_info(**options),\n  File \"C:\\Users\\Siddhi Waghmare\\AppData\\Roaming\\Python\\Python39\\site-packages\\websocket\\_http.py\", line 122, in connect\n    addrinfo_list, need_tunnel, auth = _get_addrinfo_list(\n  File \"C:\\Users\\Siddhi Waghmare\\AppData\\Roaming\\Python\\Python39\\site-packages\\websocket\\_http.py\", line 167, in _get_addrinfo_list\n    raise WebSocketAddressException(e)\nwebsocket._exceptions.WebSocketAddressException: [Errno 11001] getaddrinfo failed\n\nDuring handling of the above exception, another exception occurred:\n\nTraceback (most recent call last):\n  File \"C:\\Users\\Siddhi Waghmare\\AppData\\Roaming\\Python\\Python39\\site-packages\\websocket\\_app.py\", line 547, in _callback\n    callback(self, *args)\n  File \"C:\\Users\\Siddhi Waghmare\\AppData\\Roaming\\Python\\Python39\\site-packages\\fyers_apiv3\\FyersWebsocket\\data_ws.py\", line 1663, in <lambda>\n    on_error=lambda ws, msg: self.On_error(msg),\n  File \"C:\\Users\\Siddhi Waghmare\\AppData\\Roaming\\Python\\Python39\\site-packages\\fyers_apiv3\\FyersWebsocket\\data_ws.py\", line 1500, in On_error\n    self.OnError(message)\n  File \"c:\\Users\\Siddhi Waghmare\\Desktop\\Projects\\Trade_Executor\\backend\\webscoket_test.py\", line 21, in onerror\n    def onclose(message):\n  File \"C:\\Program Files\\Python39\\lib\\encodings\\cp1252.py\", line 19, in encode\n    return codecs.charmap_encode(input,self.errors,encoding_table)[0]\nUnicodeEncodeError: 'charmap' codec can't encode character '\\u274c' in position 0: character maps to <undefined>\n\nDuring handling of the above exception, another exception occurred:\n\nTraceback (most recent call last):\n  File \"C:\\Users\\Siddhi Waghmare\\AppData\\Roaming\\Python\\Python39\\site-packages\\websocket\\_app.py\", line 501, in run_forever\n    setSock()\n  File \"C:\\Users\\Siddhi Waghmare\\AppData\\Roaming\\Python\\Python39\\site-packages\\websocket\\_app.py\", line 430, in setSock\n    handleDisconnect(e, reconnecting)\n  File \"C:\\Users\\Siddhi Waghmare\\AppData\\Roaming\\Python\\Python39\\site-packages\\websocket\\_app.py\", line 481, in handleDisconnect\n    self._callback(self.on_error, e)\n  File \"C:\\Users\\Siddhi Waghmare\\AppData\\Roaming\\Python\\Python39\\site-packages\\websocket\\_app.py\", line 552, in _callback\n    self.on_error(self, e)\n  File \"C:\\Users\\Siddhi Waghmare\\AppData\\Roaming\\Python\\Python39\\site-packages\\fyers_apiv3\\FyersWebsocket\\data_ws.py\", line 1663, in <lambda>\n    on_error=lambda ws, msg: self.On_error(msg),\n  File \"C:\\Users\\Siddhi Waghmare\\AppData\\Roaming\\Python\\Python39\\site-packages\\fyers_apiv3\\FyersWebsocket\\data_ws.py\", line 1500, in On_error\n    self.OnError(message)\n  File \"c:\\Users\\Siddhi Waghmare\\Desktop\\Projects\\Trade_Executor\\backend\\webscoket_test.py\", line 21, in onerror\n    def onclose(message):\n  File \"C:\\Program Files\\Python39\\lib\\encodings\\cp1252.py\", line 19, in encode\n    return codecs.charmap_encode(input,self.errors,encoding_table)[0]\nUnicodeEncodeError: 'charmap' codec can't encode character '\\u274c' in position 0: character maps to <undefined>\n\nDuring handling of the above exception, another exception occurred:\n\nTraceback (most recent call last):\n  File \"C:\\Users\\Siddhi Waghmare\\AppData\\Roaming\\Python\\Python39\\site-packages\\urllib3\\connection.py\", line 174, in _new_conn\n    conn = connection.create_connection(\n  File \"C:\\Users\\Siddhi Waghmare\\AppData\\Roaming\\Python\\Python39\\site-packages\\urllib3\\util\\connection.py\", line 72, in create_connection\n    for res in socket.getaddrinfo(host, port, family, socket.SOCK_STREAM):\n  File \"C:\\Program Files\\Python39\\lib\\socket.py\", line 953, in getaddrinfo\n    for res in _socket.getaddrinfo(host, port, family, type, proto, flags):\nsocket.gaierror: [Errno 11001] getaddrinfo failed\n\nDuring handling of the above exception, another exception occurred:\n\nTraceback (most recent call last):\n  File \"C:\\Users\\Siddhi Waghmare\\AppData\\Roaming\\Python\\Python39\\site-packages\\urllib3\\connectionpool.py\", line 716, in urlopen\n    httplib_response = self._make_request(\n  File \"C:\\Users\\Siddhi Waghmare\\AppData\\Roaming\\Python\\Python39\\site-packages\\urllib3\\connectionpool.py\", line 404, in _make_request\n    self._validate_conn(conn)\n  File \"C:\\Users\\Siddhi Waghmare\\AppData\\Roaming\\Python\\Python39\\site-packages\\urllib3\\connectionpool.py\", line 1061, in _validate_conn\n    conn.connect()\n  File \"C:\\Users\\Siddhi Waghmare\\AppData\\Roaming\\Python\\Python39\\site-packages\\urllib3\\connection.py\", line 363, in connect\n    self.sock = conn = self._new_conn()\n  File \"C:\\Users\\Siddhi Waghmare\\AppData\\Roaming\\Python\\Python39\\site-packages\\urllib3\\connection.py\", line 186, in _new_conn\n    raise NewConnectionError(\nurllib3.exceptions.NewConnectionError: <urllib3.connection.HTTPSConnection object at 0x000001D155E0B070>: Failed to establish a new connection: [Errno 11001] getaddrinfo failed\n\nDuring handling of the above exception, another exception occurred:\n\nTraceback (most recent call last):\n  File \"C:\\Users\\Siddhi Waghmare\\AppData\\Roaming\\Python\\Python39\\site-packages\\requests\\adapters.py\", line 486, in send\n    resp = conn.urlopen(\n  File \"C:\\Users\\Siddhi Waghmare\\AppData\\Roaming\\Python\\Python39\\site-packages\\urllib3\\connectionpool.py\", line 802, in urlopen\n    retries = retries.increment(\n  File \"C:\\Users\\Siddhi Waghmare\\AppData\\Roaming\\Python\\Python39\\site-packages\\urllib3\\util\\retry.py\", line 594, in increment\n    raise MaxRetryError(_pool, url, error or ResponseError(cause))\nurllib3.exceptions.MaxRetryError: HTTPSConnectionPool(host='api-t1.fyers.in', port=443): Max retries exceeded with url: /data/symbol-token (Caused by NewConnectionError('<urllib3.connection.HTTPSConnection object at 0x000001D155E0B070>: Failed to establish a new connection: [Errno 11001] getaddrinfo failed'))\n\nDuring handling of the above exception, another exception occurred:\n\nTraceback (most recent call last):\n  File \"C:\\Users\\Siddhi Waghmare\\AppData\\Roaming\\Python\\Python39\\site-packages\\fyers_apiv3\\FyersWebsocket\\data_ws.py\", line 63, in symbol_to_hsmtoken\n    response = requests.post(\n  File \"C:\\Users\\Siddhi Waghmare\\AppData\\Roaming\\Python\\Python39\\site-packages\\requests\\api.py\", line 115, in post\n    return request(\"post\", url, data=data, json=json, **kwargs)\n  File \"C:\\Users\\Siddhi Waghmare\\AppData\\Roaming\\Python\\Python39\\site-packages\\requests\\api.py\", line 59, in request\n    return session.request(method=method, url=url, **kwargs)\n  File \"C:\\Users\\Siddhi Waghmare\\AppData\\Roaming\\Python\\Python39\\site-packages\\requests\\sessions.py\", line 589, in request\n    resp = self.send(prep, **send_kwargs)\n  File \"C:\\Users\\Siddhi Waghmare\\AppData\\Roaming\\Python\\Python39\\site-packages\\requests\\sessions.py\", line 703, in send\n    r = adapter.send(request, **kwargs)\n  File \"C:\\Users\\Siddhi Waghmare\\AppData\\Roaming\\Python\\Python39\\site-packages\\requests\\adapters.py\", line 519, in send\n    raise ConnectionError(e, request=request)\nrequests.exceptions.ConnectionError: HTTPSConnectionPool(host='api-t1.fyers.in', port=443): Max retries exceeded with url: /data/symbol-token (Caused by NewConnectionError('<urllib3.connection.HTTPSConnection object at 0x000001D155E0B070>: Failed to establish a new connection: [Errno 11001] getaddrinfo failed'))","exception_name":"ConnectionError"}
{"level":"ERROR","location":"[exception:108] fyers_logger","message":"'NoneType' object is not subscriptable","timestamp":"2025-06-25 19:49:34,154+0530","service":"FyersDataSocket","exception":"Traceback (most recent call last):\n  File \"C:\\Users\\Siddhi Waghmare\\AppData\\Roaming\\Python\\Python39\\site-packages\\websocket\\_http.py\", line 155, in _get_addrinfo_list\n    addrinfo_list = socket.getaddrinfo(\n  File \"C:\\Program Files\\Python39\\lib\\socket.py\", line 953, in getaddrinfo\n    for res in _socket.getaddrinfo(host, port, family, type, proto, flags):\nsocket.gaierror: [Errno 11001] getaddrinfo failed\n\nDuring handling of the above exception, another exception occurred:\n\nTraceback (most recent call last):\n  File \"C:\\Users\\Siddhi Waghmare\\AppData\\Roaming\\Python\\Python39\\site-packages\\websocket\\_app.py\", line 412, in setSock\n    self.sock.connect(\n  File \"C:\\Users\\Siddhi Waghmare\\AppData\\Roaming\\Python\\Python39\\site-packages\\websocket\\_core.py\", line 249, in connect\n    self.sock, addrs = connect(url, self.sock_opt, proxy_info(**options),\n  File \"C:\\Users\\Siddhi Waghmare\\AppData\\Roaming\\Python\\Python39\\site-packages\\websocket\\_http.py\", line 122, in connect\n    addrinfo_list, need_tunnel, auth = _get_addrinfo_list(\n  File \"C:\\Users\\Siddhi Waghmare\\AppData\\Roaming\\Python\\Python39\\site-packages\\websocket\\_http.py\", line 167, in _get_addrinfo_list\n    raise WebSocketAddressException(e)\nwebsocket._exceptions.WebSocketAddressException: [Errno 11001] getaddrinfo failed\n\nDuring handling of the above exception, another exception occurred:\n\nTraceback (most recent call last):\n  File \"C:\\Users\\Siddhi Waghmare\\AppData\\Roaming\\Python\\Python39\\site-packages\\websocket\\_app.py\", line 547, in _callback\n    callback(self, *args)\n  File \"C:\\Users\\Siddhi Waghmare\\AppData\\Roaming\\Python\\Python39\\site-packages\\fyers_apiv3\\FyersWebsocket\\data_ws.py\", line 1663, in <lambda>\n    on_error=lambda ws, msg: self.On_error(msg),\n  File \"C:\\Users\\Siddhi Waghmare\\AppData\\Roaming\\Python\\Python39\\site-packages\\fyers_apiv3\\FyersWebsocket\\data_ws.py\", line 1500, in On_error\n    self.OnError(message)\n  File \"c:\\Users\\Siddhi Waghmare\\Desktop\\Projects\\Trade_Executor\\backend\\webscoket_test.py\", line 21, in onerror\n    def onclose(message):\n  File \"C:\\Program Files\\Python39\\lib\\encodings\\cp1252.py\", line 19, in encode\n    return codecs.charmap_encode(input,self.errors,encoding_table)[0]\nUnicodeEncodeError: 'charmap' codec can't encode character '\\u274c' in position 0: character maps to <undefined>\n\nDuring handling of the above exception, another exception occurred:\n\nTraceback (most recent call last):\n  File \"C:\\Users\\Siddhi Waghmare\\AppData\\Roaming\\Python\\Python39\\site-packages\\websocket\\_app.py\", line 501, in run_forever\n    setSock()\n  File \"C:\\Users\\Siddhi Waghmare\\AppData\\Roaming\\Python\\Python39\\site-packages\\websocket\\_app.py\", line 430, in setSock\n    handleDisconnect(e, reconnecting)\n  File \"C:\\Users\\Siddhi Waghmare\\AppData\\Roaming\\Python\\Python39\\site-packages\\websocket\\_app.py\", line 481, in handleDisconnect\n    self._callback(self.on_error, e)\n  File \"C:\\Users\\Siddhi Waghmare\\AppData\\Roaming\\Python\\Python39\\site-packages\\websocket\\_app.py\", line 552, in _callback\n    self.on_error(self, e)\n  File \"C:\\Users\\Siddhi Waghmare\\AppData\\Roaming\\Python\\Python39\\site-packages\\fyers_apiv3\\FyersWebsocket\\data_ws.py\", line 1663, in <lambda>\n    on_error=lambda ws, msg: self.On_error(msg),\n  File \"C:\\Users\\Siddhi Waghmare\\AppData\\Roaming\\Python\\Python39\\site-packages\\fyers_apiv3\\FyersWebsocket\\data_ws.py\", line 1500, in On_error\n    self.OnError(message)\n  File \"c:\\Users\\Siddhi Waghmare\\Desktop\\Projects\\Trade_Executor\\backend\\webscoket_test.py\", line 21, in onerror\n    def onclose(message):\n  File \"C:\\Program Files\\Python39\\lib\\encodings\\cp1252.py\", line 19, in encode\n    return codecs.charmap_encode(input,self.errors,encoding_table)[0]\nUnicodeEncodeError: 'charmap' codec can't encode character '\\u274c' in position 0: character maps to <undefined>\n\nDuring handling of the above exception, another exception occurred:\n\nTraceback (most recent call last):\n  File \"C:\\Users\\Siddhi Waghmare\\AppData\\Roaming\\Python\\Python39\\site-packages\\fyers_apiv3\\FyersWebsocket\\data_ws.py\", line 1333, in __symbol_conversion\n    if symbol_value[3] != \"\":\nTypeError: 'NoneType' object is not subscriptable","exception_name":"TypeError"}
{"level":"ERROR","location":"[exception:108] fyers_logger","message":"HTTPSConnectionPool(host='api-t1.fyers.in', port=443): Max retries exceeded with url: /data/symbol-token (Caused by NewConnectionError('<urllib3.connection.HTTPSConnection object at 0x000001D155E0B910>: Failed to establish a new connection: [Errno 11001] getaddrinfo failed'))","timestamp":"2025-06-25 19:49:39,176+0530","service":"FyersDataSocket","exception":"Traceback (most recent call last):\n  File \"C:\\Users\\Siddhi Waghmare\\AppData\\Roaming\\Python\\Python39\\site-packages\\websocket\\_http.py\", line 155, in _get_addrinfo_list\n    addrinfo_list = socket.getaddrinfo(\n  File \"C:\\Program Files\\Python39\\lib\\socket.py\", line 953, in getaddrinfo\n    for res in _socket.getaddrinfo(host, port, family, type, proto, flags):\nsocket.gaierror: [Errno 11001] getaddrinfo failed\n\nDuring handling of the above exception, another exception occurred:\n\nTraceback (most recent call last):\n  File \"C:\\Users\\Siddhi Waghmare\\AppData\\Roaming\\Python\\Python39\\site-packages\\websocket\\_app.py\", line 412, in setSock\n    self.sock.connect(\n  File \"C:\\Users\\Siddhi Waghmare\\AppData\\Roaming\\Python\\Python39\\site-packages\\websocket\\_core.py\", line 249, in connect\n    self.sock, addrs = connect(url, self.sock_opt, proxy_info(**options),\n  File \"C:\\Users\\Siddhi Waghmare\\AppData\\Roaming\\Python\\Python39\\site-packages\\websocket\\_http.py\", line 122, in connect\n    addrinfo_list, need_tunnel, auth = _get_addrinfo_list(\n  File \"C:\\Users\\Siddhi Waghmare\\AppData\\Roaming\\Python\\Python39\\site-packages\\websocket\\_http.py\", line 167, in _get_addrinfo_list\n    raise WebSocketAddressException(e)\nwebsocket._exceptions.WebSocketAddressException: [Errno 11001] getaddrinfo failed\n\nDuring handling of the above exception, another exception occurred:\n\nTraceback (most recent call last):\n  File \"C:\\Users\\Siddhi Waghmare\\AppData\\Roaming\\Python\\Python39\\site-packages\\websocket\\_app.py\", line 547, in _callback\n    callback(self, *args)\n  File \"C:\\Users\\Siddhi Waghmare\\AppData\\Roaming\\Python\\Python39\\site-packages\\fyers_apiv3\\FyersWebsocket\\data_ws.py\", line 1663, in <lambda>\n    on_error=lambda ws, msg: self.On_error(msg),\n  File \"C:\\Users\\Siddhi Waghmare\\AppData\\Roaming\\Python\\Python39\\site-packages\\fyers_apiv3\\FyersWebsocket\\data_ws.py\", line 1500, in On_error\n    self.OnError(message)\n  File \"c:\\Users\\Siddhi Waghmare\\Desktop\\Projects\\Trade_Executor\\backend\\webscoket_test.py\", line 21, in onerror\n    def onclose(message):\n  File \"C:\\Program Files\\Python39\\lib\\encodings\\cp1252.py\", line 19, in encode\n    return codecs.charmap_encode(input,self.errors,encoding_table)[0]\nUnicodeEncodeError: 'charmap' codec can't encode character '\\u274c' in position 0: character maps to <undefined>\n\nDuring handling of the above exception, another exception occurred:\n\nTraceback (most recent call last):\n  File \"C:\\Users\\Siddhi Waghmare\\AppData\\Roaming\\Python\\Python39\\site-packages\\websocket\\_app.py\", line 501, in run_forever\n    setSock()\n  File \"C:\\Users\\Siddhi Waghmare\\AppData\\Roaming\\Python\\Python39\\site-packages\\websocket\\_app.py\", line 430, in setSock\n    handleDisconnect(e, reconnecting)\n  File \"C:\\Users\\Siddhi Waghmare\\AppData\\Roaming\\Python\\Python39\\site-packages\\websocket\\_app.py\", line 481, in handleDisconnect\n    self._callback(self.on_error, e)\n  File \"C:\\Users\\Siddhi Waghmare\\AppData\\Roaming\\Python\\Python39\\site-packages\\websocket\\_app.py\", line 552, in _callback\n    self.on_error(self, e)\n  File \"C:\\Users\\Siddhi Waghmare\\AppData\\Roaming\\Python\\Python39\\site-packages\\fyers_apiv3\\FyersWebsocket\\data_ws.py\", line 1663, in <lambda>\n    on_error=lambda ws, msg: self.On_error(msg),\n  File \"C:\\Users\\Siddhi Waghmare\\AppData\\Roaming\\Python\\Python39\\site-packages\\fyers_apiv3\\FyersWebsocket\\data_ws.py\", line 1500, in On_error\n    self.OnError(message)\n  File \"c:\\Users\\Siddhi Waghmare\\Desktop\\Projects\\Trade_Executor\\backend\\webscoket_test.py\", line 21, in onerror\n    def onclose(message):\n  File \"C:\\Program Files\\Python39\\lib\\encodings\\cp1252.py\", line 19, in encode\n    return codecs.charmap_encode(input,self.errors,encoding_table)[0]\nUnicodeEncodeError: 'charmap' codec can't encode character '\\u274c' in position 0: character maps to <undefined>\n\nDuring handling of the above exception, another exception occurred:\n\nTraceback (most recent call last):\n  File \"C:\\Users\\Siddhi Waghmare\\AppData\\Roaming\\Python\\Python39\\site-packages\\urllib3\\connection.py\", line 174, in _new_conn\n    conn = connection.create_connection(\n  File \"C:\\Users\\Siddhi Waghmare\\AppData\\Roaming\\Python\\Python39\\site-packages\\urllib3\\util\\connection.py\", line 72, in create_connection\n    for res in socket.getaddrinfo(host, port, family, socket.SOCK_STREAM):\n  File \"C:\\Program Files\\Python39\\lib\\socket.py\", line 953, in getaddrinfo\n    for res in _socket.getaddrinfo(host, port, family, type, proto, flags):\nsocket.gaierror: [Errno 11001] getaddrinfo failed\n\nDuring handling of the above exception, another exception occurred:\n\nTraceback (most recent call last):\n  File \"C:\\Users\\Siddhi Waghmare\\AppData\\Roaming\\Python\\Python39\\site-packages\\urllib3\\connectionpool.py\", line 716, in urlopen\n    httplib_response = self._make_request(\n  File \"C:\\Users\\Siddhi Waghmare\\AppData\\Roaming\\Python\\Python39\\site-packages\\urllib3\\connectionpool.py\", line 404, in _make_request\n    self._validate_conn(conn)\n  File \"C:\\Users\\Siddhi Waghmare\\AppData\\Roaming\\Python\\Python39\\site-packages\\urllib3\\connectionpool.py\", line 1061, in _validate_conn\n    conn.connect()\n  File \"C:\\Users\\Siddhi Waghmare\\AppData\\Roaming\\Python\\Python39\\site-packages\\urllib3\\connection.py\", line 363, in connect\n    self.sock = conn = self._new_conn()\n  File \"C:\\Users\\Siddhi Waghmare\\AppData\\Roaming\\Python\\Python39\\site-packages\\urllib3\\connection.py\", line 186, in _new_conn\n    raise NewConnectionError(\nurllib3.exceptions.NewConnectionError: <urllib3.connection.HTTPSConnection object at 0x000001D155E0B910>: Failed to establish a new connection: [Errno 11001] getaddrinfo failed\n\nDuring handling of the above exception, another exception occurred:\n\nTraceback (most recent call last):\n  File \"C:\\Users\\Siddhi Waghmare\\AppData\\Roaming\\Python\\Python39\\site-packages\\requests\\adapters.py\", line 486, in send\n    resp = conn.urlopen(\n  File \"C:\\Users\\Siddhi Waghmare\\AppData\\Roaming\\Python\\Python39\\site-packages\\urllib3\\connectionpool.py\", line 802, in urlopen\n    retries = retries.increment(\n  File \"C:\\Users\\Siddhi Waghmare\\AppData\\Roaming\\Python\\Python39\\site-packages\\urllib3\\util\\retry.py\", line 594, in increment\n    raise MaxRetryError(_pool, url, error or ResponseError(cause))\nurllib3.exceptions.MaxRetryError: HTTPSConnectionPool(host='api-t1.fyers.in', port=443): Max retries exceeded with url: /data/symbol-token (Caused by NewConnectionError('<urllib3.connection.HTTPSConnection object at 0x000001D155E0B910>: Failed to establish a new connection: [Errno 11001] getaddrinfo failed'))\n\nDuring handling of the above exception, another exception occurred:\n\nTraceback (most recent call last):\n  File \"C:\\Users\\Siddhi Waghmare\\AppData\\Roaming\\Python\\Python39\\site-packages\\fyers_apiv3\\FyersWebsocket\\data_ws.py\", line 63, in symbol_to_hsmtoken\n    response = requests.post(\n  File \"C:\\Users\\Siddhi Waghmare\\AppData\\Roaming\\Python\\Python39\\site-packages\\requests\\api.py\", line 115, in post\n    return request(\"post\", url, data=data, json=json, **kwargs)\n  File \"C:\\Users\\Siddhi Waghmare\\AppData\\Roaming\\Python\\Python39\\site-packages\\requests\\api.py\", line 59, in request\n    return session.request(method=method, url=url, **kwargs)\n  File \"C:\\Users\\Siddhi Waghmare\\AppData\\Roaming\\Python\\Python39\\site-packages\\requests\\sessions.py\", line 589, in request\n    resp = self.send(prep, **send_kwargs)\n  File \"C:\\Users\\Siddhi Waghmare\\AppData\\Roaming\\Python\\Python39\\site-packages\\requests\\sessions.py\", line 703, in send\n    r = adapter.send(request, **kwargs)\n  File \"C:\\Users\\Siddhi Waghmare\\AppData\\Roaming\\Python\\Python39\\site-packages\\requests\\adapters.py\", line 519, in send\n    raise ConnectionError(e, request=request)\nrequests.exceptions.ConnectionError: HTTPSConnectionPool(host='api-t1.fyers.in', port=443): Max retries exceeded with url: /data/symbol-token (Caused by NewConnectionError('<urllib3.connection.HTTPSConnection object at 0x000001D155E0B910>: Failed to establish a new connection: [Errno 11001] getaddrinfo failed'))","exception_name":"ConnectionError"}
{"level":"ERROR","location":"[exception:108] fyers_logger","message":"'NoneType' object is not subscriptable","timestamp":"2025-06-25 19:49:39,178+0530","service":"FyersDataSocket","exception":"Traceback (most recent call last):\n  File \"C:\\Users\\Siddhi Waghmare\\AppData\\Roaming\\Python\\Python39\\site-packages\\websocket\\_http.py\", line 155, in _get_addrinfo_list\n    addrinfo_list = socket.getaddrinfo(\n  File \"C:\\Program Files\\Python39\\lib\\socket.py\", line 953, in getaddrinfo\n    for res in _socket.getaddrinfo(host, port, family, type, proto, flags):\nsocket.gaierror: [Errno 11001] getaddrinfo failed\n\nDuring handling of the above exception, another exception occurred:\n\nTraceback (most recent call last):\n  File \"C:\\Users\\Siddhi Waghmare\\AppData\\Roaming\\Python\\Python39\\site-packages\\websocket\\_app.py\", line 412, in setSock\n    self.sock.connect(\n  File \"C:\\Users\\Siddhi Waghmare\\AppData\\Roaming\\Python\\Python39\\site-packages\\websocket\\_core.py\", line 249, in connect\n    self.sock, addrs = connect(url, self.sock_opt, proxy_info(**options),\n  File \"C:\\Users\\Siddhi Waghmare\\AppData\\Roaming\\Python\\Python39\\site-packages\\websocket\\_http.py\", line 122, in connect\n    addrinfo_list, need_tunnel, auth = _get_addrinfo_list(\n  File \"C:\\Users\\Siddhi Waghmare\\AppData\\Roaming\\Python\\Python39\\site-packages\\websocket\\_http.py\", line 167, in _get_addrinfo_list\n    raise WebSocketAddressException(e)\nwebsocket._exceptions.WebSocketAddressException: [Errno 11001] getaddrinfo failed\n\nDuring handling of the above exception, another exception occurred:\n\nTraceback (most recent call last):\n  File \"C:\\Users\\Siddhi Waghmare\\AppData\\Roaming\\Python\\Python39\\site-packages\\websocket\\_app.py\", line 547, in _callback\n    callback(self, *args)\n  File \"C:\\Users\\Siddhi Waghmare\\AppData\\Roaming\\Python\\Python39\\site-packages\\fyers_apiv3\\FyersWebsocket\\data_ws.py\", line 1663, in <lambda>\n    on_error=lambda ws, msg: self.On_error(msg),\n  File \"C:\\Users\\Siddhi Waghmare\\AppData\\Roaming\\Python\\Python39\\site-packages\\fyers_apiv3\\FyersWebsocket\\data_ws.py\", line 1500, in On_error\n    self.OnError(message)\n  File \"c:\\Users\\Siddhi Waghmare\\Desktop\\Projects\\Trade_Executor\\backend\\webscoket_test.py\", line 21, in onerror\n    def onclose(message):\n  File \"C:\\Program Files\\Python39\\lib\\encodings\\cp1252.py\", line 19, in encode\n    return codecs.charmap_encode(input,self.errors,encoding_table)[0]\nUnicodeEncodeError: 'charmap' codec can't encode character '\\u274c' in position 0: character maps to <undefined>\n\nDuring handling of the above exception, another exception occurred:\n\nTraceback (most recent call last):\n  File \"C:\\Users\\Siddhi Waghmare\\AppData\\Roaming\\Python\\Python39\\site-packages\\websocket\\_app.py\", line 501, in run_forever\n    setSock()\n  File \"C:\\Users\\Siddhi Waghmare\\AppData\\Roaming\\Python\\Python39\\site-packages\\websocket\\_app.py\", line 430, in setSock\n    handleDisconnect(e, reconnecting)\n  File \"C:\\Users\\Siddhi Waghmare\\AppData\\Roaming\\Python\\Python39\\site-packages\\websocket\\_app.py\", line 481, in handleDisconnect\n    self._callback(self.on_error, e)\n  File \"C:\\Users\\Siddhi Waghmare\\AppData\\Roaming\\Python\\Python39\\site-packages\\websocket\\_app.py\", line 552, in _callback\n    self.on_error(self, e)\n  File \"C:\\Users\\Siddhi Waghmare\\AppData\\Roaming\\Python\\Python39\\site-packages\\fyers_apiv3\\FyersWebsocket\\data_ws.py\", line 1663, in <lambda>\n    on_error=lambda ws, msg: self.On_error(msg),\n  File \"C:\\Users\\Siddhi Waghmare\\AppData\\Roaming\\Python\\Python39\\site-packages\\fyers_apiv3\\FyersWebsocket\\data_ws.py\", line 1500, in On_error\n    self.OnError(message)\n  File \"c:\\Users\\Siddhi Waghmare\\Desktop\\Projects\\Trade_Executor\\backend\\webscoket_test.py\", line 21, in onerror\n    def onclose(message):\n  File \"C:\\Program Files\\Python39\\lib\\encodings\\cp1252.py\", line 19, in encode\n    return codecs.charmap_encode(input,self.errors,encoding_table)[0]\nUnicodeEncodeError: 'charmap' codec can't encode character '\\u274c' in position 0: character maps to <undefined>\n\nDuring handling of the above exception, another exception occurred:\n\nTraceback (most recent call last):\n  File \"C:\\Users\\Siddhi Waghmare\\AppData\\Roaming\\Python\\Python39\\site-packages\\fyers_apiv3\\FyersWebsocket\\data_ws.py\", line 1333, in __symbol_conversion\n    if symbol_value[3] != \"\":\nTypeError: 'NoneType' object is not subscriptable","exception_name":"TypeError"}
